{
  "name": "Export",
  "version": "1.0",
  "createdAt": "2026-03-20T06:03:37.460Z",
  "gridSize": 64,
  "voxelCount": 54,
  "voxels": [
    {
      "x": 33,
      "y": 32,
      "z": 34,
      "type": "thruster"
    },
    {
      "x": 33,
      "y": 32,
      "z": 35,
      "type": "solar_panel"
    },
    {
      "x": 33,
      "y": 32,
      "z": 36,
      "type": "solar_panel"
    },
    {
      "x": 33,
      "y": 33,
      "z": 34,
      "type": "thruster"
    },
    {
      "x": 33,
      "y": 34,
      "z": 34,
      "type": "turret_mount"
    },
    {
      "x": 33,
      "y": 35,
      "z": 34,
      "type": "turret_mount"
    },
    {
      "x": 33,
      "y": 35,
      "z": 35,
      "type": "turret_mount"
    },
    {
      "x": 33,
      "y": 36,
      "z": 34,
      "type": "turret_mount"
    },
    {
      "x": 33,
      "y": 36,
      "z": 35,
      "type": "turret_mount"
    },
    {
      "x": 33,
      "y": 36,
      "z": 36,
      "type": "turret_mount"
    },
    {
      "x": 33,
      "y": 36,
      "z": 37,
      "type": "turret_mount"
    },
    {
      "x": 33,
      "y": 37,
      "z": 34,
      "type": "turret_mount"
    },
    {
      "x": 33,
      "y": 38,
      "z": 34,
      "type": "turret_mount"
    },
    {
      "x": 34,
      "y": 32,
      "z": 34,
      "type": "thruster"
    },
    {
      "x": 34,
      "y": 32,
      "z": 35,
      "type": "hull_medium"
    },
    {
      "x": 34,
      "y": 32,
      "z": 36,
      "type": "solar_panel"
    },
    {
      "x": 34,
      "y": 33,
      "z": 34,
      "type": "thruster"
    },
    {
      "x": 34,
      "y": 33,
      "z": 35,
      "type": "thruster"
    },
    {
      "x": 34,
      "y": 35,
      "z": 34,
      "type": "turret_mount"
    },
    {
      "x": 34,
      "y": 38,
      "z": 34,
      "type": "turret_mount"
    },
    {
      "x": 34,
      "y": 39,
      "z": 34,
      "type": "light"
    },
    {
      "x": 35,
      "y": 32,
      "z": 34,
      "type": "thruster"
    },
    {
      "x": 35,
      "y": 32,
      "z": 35,
      "type": "hull_medium"
    },
    {
      "x": 35,
      "y": 32,
      "z": 36,
      "type": "solar_panel"
    },
    {
      "x": 35,
      "y": 33,
      "z": 34,
      "type": "thruster"
    },
    {
      "x": 35,
      "y": 35,
      "z": 34,
      "type": "turret_mount"
    },
    {
      "x": 35,
      "y": 38,
      "z": 34,
      "type": "turret_mount"
    },
    {
      "x": 35,
      "y": 39,
      "z": 34,
      "type": "light"
    },
    {
      "x": 35,
      "y": 40,
      "z": 34,
      "type": "light"
    },
    {
      "x": 36,
      "y": 32,
      "z": 34,
      "type": "thruster"
    },
    {
      "x": 36,
      "y": 32,
      "z": 35,
      "type": "hull_medium"
    },
    {
      "x": 36,
      "y": 32,
      "z": 36,
      "type": "solar_panel"
    },
    {
      "x": 36,
      "y": 33,
      "z": 34,
      "type": "thruster"
    },
    {
      "x": 36,
      "y": 33,
      "z": 35,
      "type": "thruster"
    },
    {
      "x": 36,
      "y": 35,
      "z": 34,
      "type": "turret_mount"
    },
    {
      "x": 36,
      "y": 38,
      "z": 34,
      "type": "turret_mount"
    },
    {
      "x": 36,
      "y": 39,
      "z": 34,
      "type": "light"
    },
    {
      "x": 36,
      "y": 40,
      "z": 34,
      "type": "light"
    },
    {
      "x": 37,
      "y": 32,
      "z": 34,
      "type": "thruster"
    },
    {
      "x": 37,
      "y": 32,
      "z": 35,
      "type": "solar_panel"
    },
    {
      "x": 37,
      "y": 32,
      "z": 36,
      "type": "solar_panel"
    },
    {
      "x": 37,
      "y": 33,
      "z": 34,
      "type": "thruster"
    },
    {
      "x": 37,
      "y": 34,
      "z": 34,
      "type": "turret_mount"
    },
    {
      "x": 37,
      "y": 35,
      "z": 34,
      "type": "turret_mount"
    },
    {
      "x": 37,
      "y": 38,
      "z": 34,
      "type": "turret_mount"
    },
    {
      "x": 37,
      "y": 39,
      "z": 34,
      "type": "light"
    },
    {
      "x": 38,
      "y": 34,
      "z": 34,
      "type": "turret_mount"
    },
    {
      "x": 38,
      "y": 35,
      "z": 34,
      "type": "turret_mount"
    },
    {
      "x": 38,
      "y": 36,
      "z": 34,
      "type": "turret_mount"
    },
    {
      "x": 38,
      "y": 36,
      "z": 35,
      "type": "turret_mount"
    },
    {
      "x": 38,
      "y": 36,
      "z": 36,
      "type": "turret_mount"
    },
    {
      "x": 38,
      "y": 36,
      "z": 37,
      "type": "turret_mount"
    },
    {
      "x": 38,
      "y": 37,
      "z": 34,
      "type": "turret_mount"
    },
    {
      "x": 38,
      "y": 38,
      "z": 34,
      "type": "turret_mount"
    }
  ]
}