{
  "name": "Export",
  "version": "1.0",
  "createdAt": "2026-03-14T13:37:10.580Z",
  "gridSize": 64,
  "voxelCount": 101,
  "voxels": [
    {
      "x": 29,
      "y": 32,
      "z": 35,
      "type": "shield_gen"
    },
    {
      "x": 30,
      "y": 32,
      "z": 39,
      "type": "turret_mount"
    },
    {
      "x": 31,
      "y": 32,
      "z": 28,
      "type": "turret_mount"
    },
    {
      "x": 31,
      "y": 32,
      "z": 31,
      "type": "turret_mount"
    },
    {
      "x": 32,
      "y": 32,
      "z": 25,
      "type": "docking_port"
    },
    {
      "x": 32,
      "y": 32,
      "z": 36,
      "type": "turret_mount"
    },
    {
      "x": 32,
      "y": 32,
      "z": 37,
      "type": "turret_mount"
    },
    {
      "x": 32,
      "y": 32,
      "z": 38,
      "type": "turret_mount"
    },
    {
      "x": 32,
      "y": 32,
      "z": 40,
      "type": "thruster"
    },
    {
      "x": 32,
      "y": 33,
      "z": 36,
      "type": "turret_mount"
    },
    {
      "x": 32,
      "y": 33,
      "z": 37,
      "type": "turret_mount"
    },
    {
      "x": 32,
      "y": 33,
      "z": 38,
      "type": "turret_mount"
    },
    {
      "x": 32,
      "y": 34,
      "z": 36,
      "type": "hull_medium"
    },
    {
      "x": 32,
      "y": 34,
      "z": 37,
      "type": "turret_mount"
    },
    {
      "x": 32,
      "y": 34,
      "z": 38,
      "type": "hull_medium"
    },
    {
      "x": 32,
      "y": 35,
      "z": 36,
      "type": "hull_medium"
    },
    {
      "x": 32,
      "y": 35,
      "z": 37,
      "type": "hull_medium"
    },
    {
      "x": 32,
      "y": 35,
      "z": 38,
      "type": "hull_medium"
    },
    {
      "x": 32,
      "y": 36,
      "z": 36,
      "type": "thruster"
    },
    {
      "x": 32,
      "y": 36,
      "z": 37,
      "type": "hull_medium"
    },
    {
      "x": 32,
      "y": 36,
      "z": 38,
      "type": "thruster"
    },
    {
      "x": 32,
      "y": 37,
      "z": 36,
      "type": "shield_gen"
    },
    {
      "x": 32,
      "y": 37,
      "z": 37,
      "type": "thruster"
    },
    {
      "x": 32,
      "y": 37,
      "z": 38,
      "type": "shield_gen"
    },
    {
      "x": 32,
      "y": 38,
      "z": 36,
      "type": "cargo_bay"
    },
    {
      "x": 32,
      "y": 38,
      "z": 37,
      "type": "shield_gen"
    },
    {
      "x": 32,
      "y": 38,
      "z": 38,
      "type": "cargo_bay"
    },
    {
      "x": 33,
      "y": 32,
      "z": 36,
      "type": "thruster"
    },
    {
      "x": 33,
      "y": 32,
      "z": 37,
      "type": "turret_mount"
    },
    {
      "x": 33,
      "y": 32,
      "z": 38,
      "type": "cargo_bay"
    },
    {
      "x": 33,
      "y": 33,
      "z": 36,
      "type": "thruster"
    },
    {
      "x": 33,
      "y": 33,
      "z": 37,
      "type": "turret_mount"
    },
    {
      "x": 33,
      "y": 34,
      "z": 36,
      "type": "thruster"
    },
    {
      "x": 33,
      "y": 34,
      "z": 37,
      "type": "turret_mount"
    },
    {
      "x": 33,
      "y": 35,
      "z": 36,
      "type": "thruster"
    },
    {
      "x": 33,
      "y": 35,
      "z": 37,
      "type": "hull_medium"
    },
    {
      "x": 33,
      "y": 36,
      "z": 36,
      "type": "cargo_bay"
    },
    {
      "x": 33,
      "y": 36,
      "z": 37,
      "type": "thruster"
    },
    {
      "x": 33,
      "y": 37,
      "z": 36,
      "type": "cargo_bay"
    },
    {
      "x": 33,
      "y": 38,
      "z": 36,
      "type": "docking_port"
    },
    {
      "x": 33,
      "y": 39,
      "z": 36,
      "type": "docking_port"
    },
    {
      "x": 33,
      "y": 40,
      "z": 36,
      "type": "docking_port"
    },
    {
      "x": 33,
      "y": 41,
      "z": 36,
      "type": "shield_gen"
    },
    {
      "x": 33,
      "y": 42,
      "z": 36,
      "type": "paint"
    },
    {
      "x": 33,
      "y": 43,
      "z": 36,
      "type": "cargo_bay"
    },
    {
      "x": 34,
      "y": 32,
      "z": 27,
      "type": "thruster"
    },
    {
      "x": 34,
      "y": 32,
      "z": 36,
      "type": "thruster"
    },
    {
      "x": 34,
      "y": 33,
      "z": 36,
      "type": "thruster"
    },
    {
      "x": 34,
      "y": 34,
      "z": 36,
      "type": "thruster"
    },
    {
      "x": 34,
      "y": 35,
      "z": 36,
      "type": "thruster"
    },
    {
      "x": 34,
      "y": 36,
      "z": 36,
      "type": "cargo_bay"
    },
    {
      "x": 34,
      "y": 37,
      "z": 36,
      "type": "light"
    },
    {
      "x": 34,
      "y": 38,
      "z": 36,
      "type": "docking_port"
    },
    {
      "x": 34,
      "y": 39,
      "z": 36,
      "type": "docking_port"
    },
    {
      "x": 34,
      "y": 40,
      "z": 36,
      "type": "shield_gen"
    },
    {
      "x": 34,
      "y": 41,
      "z": 36,
      "type": "paint"
    },
    {
      "x": 34,
      "y": 42,
      "z": 36,
      "type": "paint"
    },
    {
      "x": 34,
      "y": 43,
      "z": 36,
      "type": "turret_mount"
    },
    {
      "x": 34,
      "y": 44,
      "z": 36,
      "type": "cargo_bay"
    },
    {
      "x": 35,
      "y": 32,
      "z": 31,
      "type": "turret_mount"
    },
    {
      "x": 35,
      "y": 32,
      "z": 36,
      "type": "thruster"
    },
    {
      "x": 35,
      "y": 33,
      "z": 36,
      "type": "thruster"
    },
    {
      "x": 35,
      "y": 34,
      "z": 36,
      "type": "thruster"
    },
    {
      "x": 35,
      "y": 35,
      "z": 36,
      "type": "thruster"
    },
    {
      "x": 35,
      "y": 36,
      "z": 36,
      "type": "cargo_bay"
    },
    {
      "x": 35,
      "y": 37,
      "z": 36,
      "type": "docking_port"
    },
    {
      "x": 35,
      "y": 38,
      "z": 36,
      "type": "docking_port"
    },
    {
      "x": 35,
      "y": 39,
      "z": 36,
      "type": "docking_port"
    },
    {
      "x": 35,
      "y": 40,
      "z": 36,
      "type": "docking_port"
    },
    {
      "x": 35,
      "y": 41,
      "z": 36,
      "type": "shield_gen"
    },
    {
      "x": 35,
      "y": 41,
      "z": 37,
      "type": "cargo_bay"
    },
    {
      "x": 35,
      "y": 42,
      "z": 36,
      "type": "paint"
    },
    {
      "x": 35,
      "y": 43,
      "z": 36,
      "type": "turret_mount"
    },
    {
      "x": 35,
      "y": 44,
      "z": 36,
      "type": "cargo_bay"
    },
    {
      "x": 36,
      "y": 32,
      "z": 32,
      "type": "hull_medium"
    },
    {
      "x": 36,
      "y": 32,
      "z": 36,
      "type": "thruster"
    },
    {
      "x": 36,
      "y": 33,
      "z": 36,
      "type": "thruster"
    },
    {
      "x": 36,
      "y": 34,
      "z": 36,
      "type": "thruster"
    },
    {
      "x": 36,
      "y": 35,
      "z": 36,
      "type": "thruster"
    },
    {
      "x": 36,
      "y": 36,
      "z": 36,
      "type": "cargo_bay"
    },
    {
      "x": 36,
      "y": 37,
      "z": 36,
      "type": "light"
    },
    {
      "x": 36,
      "y": 38,
      "z": 36,
      "type": "docking_port"
    },
    {
      "x": 36,
      "y": 39,
      "z": 36,
      "type": "docking_port"
    },
    {
      "x": 36,
      "y": 40,
      "z": 36,
      "type": "shield_gen"
    },
    {
      "x": 36,
      "y": 41,
      "z": 36,
      "type": "paint"
    },
    {
      "x": 36,
      "y": 42,
      "z": 36,
      "type": "paint"
    },
    {
      "x": 36,
      "y": 43,
      "z": 36,
      "type": "turret_mount"
    },
    {
      "x": 36,
      "y": 44,
      "z": 36,
      "type": "cargo_bay"
    },
    {
      "x": 37,
      "y": 32,
      "z": 36,
      "type": "thruster"
    },
    {
      "x": 37,
      "y": 33,
      "z": 36,
      "type": "thruster"
    },
    {
      "x": 37,
      "y": 34,
      "z": 36,
      "type": "thruster"
    },
    {
      "x": 37,
      "y": 35,
      "z": 36,
      "type": "thruster"
    },
    {
      "x": 37,
      "y": 36,
      "z": 36,
      "type": "cargo_bay"
    },
    {
      "x": 37,
      "y": 37,
      "z": 36,
      "type": "cargo_bay"
    },
    {
      "x": 37,
      "y": 38,
      "z": 36,
      "type": "docking_port"
    },
    {
      "x": 37,
      "y": 39,
      "z": 36,
      "type": "docking_port"
    },
    {
      "x": 37,
      "y": 40,
      "z": 36,
      "type": "docking_port"
    },
    {
      "x": 37,
      "y": 41,
      "z": 36,
      "type": "shield_gen"
    },
    {
      "x": 37,
      "y": 42,
      "z": 36,
      "type": "paint"
    },
    {
      "x": 37,
      "y": 43,
      "z": 36,
      "type": "cargo_bay"
    },
    {
      "x": 41,
      "y": 32,
      "z": 28,
      "type": "shield_gen"
    }
  ]
}