{
  "name": "Export",
  "version": "1.0",
  "createdAt": "2026-03-09T10:41:21.313Z",
  "gridSize": 64,
  "voxelCount": 62,
  "voxels": [
    {
      "x": 31,
      "y": 34,
      "z": 36,
      "type": "shield_gen"
    },
    {
      "x": 31,
      "y": 34,
      "z": 37,
      "type": "shield_gen"
    },
    {
      "x": 32,
      "y": 34,
      "z": 31,
      "type": "shield_gen"
    },
    {
      "x": 32,
      "y": 34,
      "z": 32,
      "type": "shield_gen"
    },
    {
      "x": 32,
      "y": 34,
      "z": 33,
      "type": "shield_gen"
    },
    {
      "x": 32,
      "y": 34,
      "z": 34,
      "type": "shield_gen"
    },
    {
      "x": 32,
      "y": 34,
      "z": 35,
      "type": "shield_gen"
    },
    {
      "x": 32,
      "y": 34,
      "z": 36,
      "type": "shield_gen"
    },
    {
      "x": 32,
      "y": 34,
      "z": 37,
      "type": "shield_gen"
    },
    {
      "x": 33,
      "y": 31,
      "z": 35,
      "type": "solar_panel"
    },
    {
      "x": 33,
      "y": 32,
      "z": 34,
      "type": "hull_medium"
    },
    {
      "x": 33,
      "y": 32,
      "z": 35,
      "type": "hull_medium"
    },
    {
      "x": 33,
      "y": 33,
      "z": 34,
      "type": "hull_medium"
    },
    {
      "x": 33,
      "y": 33,
      "z": 35,
      "type": "hull_medium"
    },
    {
      "x": 33,
      "y": 34,
      "z": 31,
      "type": "shield_gen"
    },
    {
      "x": 33,
      "y": 34,
      "z": 32,
      "type": "shield_gen"
    },
    {
      "x": 33,
      "y": 34,
      "z": 33,
      "type": "turret_mount"
    },
    {
      "x": 33,
      "y": 34,
      "z": 34,
      "type": "turret_mount"
    },
    {
      "x": 33,
      "y": 34,
      "z": 35,
      "type": "hull_medium"
    },
    {
      "x": 33,
      "y": 34,
      "z": 36,
      "type": "turret_mount"
    },
    {
      "x": 33,
      "y": 34,
      "z": 37,
      "type": "shield_gen"
    },
    {
      "x": 33,
      "y": 35,
      "z": 33,
      "type": "thruster"
    },
    {
      "x": 33,
      "y": 35,
      "z": 34,
      "type": "thruster"
    },
    {
      "x": 33,
      "y": 35,
      "z": 35,
      "type": "thruster"
    },
    {
      "x": 33,
      "y": 35,
      "z": 36,
      "type": "thruster"
    },
    {
      "x": 34,
      "y": 31,
      "z": 35,
      "type": "solar_panel"
    },
    {
      "x": 34,
      "y": 32,
      "z": 34,
      "type": "hull_medium"
    },
    {
      "x": 34,
      "y": 32,
      "z": 35,
      "type": "hull_medium"
    },
    {
      "x": 34,
      "y": 33,
      "z": 34,
      "type": "hull_reinforced"
    },
    {
      "x": 34,
      "y": 33,
      "z": 35,
      "type": "hull_medium"
    },
    {
      "x": 34,
      "y": 34,
      "z": 32,
      "type": "shield_gen"
    },
    {
      "x": 34,
      "y": 34,
      "z": 33,
      "type": "turret_mount"
    },
    {
      "x": 34,
      "y": 34,
      "z": 34,
      "type": "hull_reinforced"
    },
    {
      "x": 34,
      "y": 34,
      "z": 35,
      "type": "hull_medium"
    },
    {
      "x": 34,
      "y": 34,
      "z": 36,
      "type": "turret_mount"
    },
    {
      "x": 34,
      "y": 34,
      "z": 37,
      "type": "shield_gen"
    },
    {
      "x": 34,
      "y": 35,
      "z": 33,
      "type": "thruster"
    },
    {
      "x": 34,
      "y": 35,
      "z": 34,
      "type": "hull_reinforced"
    },
    {
      "x": 34,
      "y": 35,
      "z": 36,
      "type": "thruster"
    },
    {
      "x": 35,
      "y": 31,
      "z": 35,
      "type": "solar_panel"
    },
    {
      "x": 35,
      "y": 32,
      "z": 35,
      "type": "turret_mount"
    },
    {
      "x": 35,
      "y": 33,
      "z": 35,
      "type": "turret_mount"
    },
    {
      "x": 35,
      "y": 34,
      "z": 32,
      "type": "shield_gen"
    },
    {
      "x": 35,
      "y": 34,
      "z": 33,
      "type": "turret_mount"
    },
    {
      "x": 35,
      "y": 34,
      "z": 34,
      "type": "turret_mount"
    },
    {
      "x": 35,
      "y": 34,
      "z": 35,
      "type": "turret_mount"
    },
    {
      "x": 35,
      "y": 34,
      "z": 36,
      "type": "turret_mount"
    },
    {
      "x": 35,
      "y": 34,
      "z": 37,
      "type": "shield_gen"
    },
    {
      "x": 35,
      "y": 34,
      "z": 38,
      "type": "shield_gen"
    },
    {
      "x": 35,
      "y": 35,
      "z": 33,
      "type": "thruster"
    },
    {
      "x": 35,
      "y": 35,
      "z": 34,
      "type": "thruster"
    },
    {
      "x": 35,
      "y": 35,
      "z": 35,
      "type": "thruster"
    },
    {
      "x": 35,
      "y": 35,
      "z": 36,
      "type": "thruster"
    },
    {
      "x": 36,
      "y": 34,
      "z": 32,
      "type": "shield_gen"
    },
    {
      "x": 36,
      "y": 34,
      "z": 33,
      "type": "shield_gen"
    },
    {
      "x": 36,
      "y": 34,
      "z": 34,
      "type": "shield_gen"
    },
    {
      "x": 36,
      "y": 34,
      "z": 35,
      "type": "shield_gen"
    },
    {
      "x": 36,
      "y": 34,
      "z": 36,
      "type": "shield_gen"
    },
    {
      "x": 36,
      "y": 34,
      "z": 37,
      "type": "shield_gen"
    },
    {
      "x": 36,
      "y": 34,
      "z": 38,
      "type": "shield_gen"
    },
    {
      "x": 37,
      "y": 34,
      "z": 32,
      "type": "shield_gen"
    },
    {
      "x": 37,
      "y": 34,
      "z": 33,
      "type": "shield_gen"
    }
  ]
}