{
  "name": "SolarWheel_Pro",
  "version": "1.0",
  "createdAt": "2026-04-11T18:06:32.268031Z",
  "gridSize": 64,
  "voxelCount": 2569,
  "voxels": [
    {
      "x": 31,
      "y": 32,
      "z": 0,
      "type": "hull_reinforced"
    },
    {
      "x": 32,
      "y": 31,
      "z": 0,
      "type": "hull_reinforced"
    },
    {
      "x": 32,
      "y": 32,
      "z": 0,
      "type": "hull_reinforced"
    },
    {
      "x": 32,
      "y": 33,
      "z": 0,
      "type": "hull_reinforced"
    },
    {
      "x": 33,
      "y": 32,
      "z": 0,
      "type": "hull_reinforced"
    },
    {
      "x": 31,
      "y": 32,
      "z": 1,
      "type": "hull_reinforced"
    },
    {
      "x": 32,
      "y": 31,
      "z": 1,
      "type": "hull_reinforced"
    },
    {
      "x": 32,
      "y": 32,
      "z": 1,
      "type": "hull_reinforced"
    },
    {
      "x": 32,
      "y": 33,
      "z": 1,
      "type": "hull_reinforced"
    },
    {
      "x": 33,
      "y": 32,
      "z": 1,
      "type": "hull_reinforced"
    },
    {
      "x": 31,
      "y": 32,
      "z": 2,
      "type": "hull_reinforced"
    },
    {
      "x": 32,
      "y": 31,
      "z": 2,
      "type": "hull_reinforced"
    },
    {
      "x": 32,
      "y": 32,
      "z": 2,
      "type": "hull_reinforced"
    },
    {
      "x": 32,
      "y": 33,
      "z": 2,
      "type": "hull_reinforced"
    },
    {
      "x": 33,
      "y": 32,
      "z": 2,
      "type": "hull_reinforced"
    },
    {
      "x": 31,
      "y": 32,
      "z": 3,
      "type": "hull_reinforced"
    },
    {
      "x": 32,
      "y": 31,
      "z": 3,
      "type": "hull_reinforced"
    },
    {
      "x": 32,
      "y": 32,
      "z": 3,
      "type": "hull_reinforced"
    },
    {
      "x": 32,
      "y": 33,
      "z": 3,
      "type": "hull_reinforced"
    },
    {
      "x": 33,
      "y": 32,
      "z": 3,
      "type": "hull_reinforced"
    },
    {
      "x": 31,
      "y": 32,
      "z": 4,
      "type": "hull_reinforced"
    },
    {
      "x": 32,
      "y": 31,
      "z": 4,
      "type": "hull_reinforced"
    },
    {
      "x": 32,
      "y": 32,
      "z": 4,
      "type": "hull_reinforced"
    },
    {
      "x": 32,
      "y": 33,
      "z": 4,
      "type": "hull_reinforced"
    },
    {
      "x": 33,
      "y": 32,
      "z": 4,
      "type": "hull_reinforced"
    },
    {
      "x": 31,
      "y": 32,
      "z": 5,
      "type": "hull_reinforced"
    },
    {
      "x": 32,
      "y": 31,
      "z": 5,
      "type": "hull_reinforced"
    },
    {
      "x": 32,
      "y": 32,
      "z": 5,
      "type": "hull_reinforced"
    },
    {
      "x": 32,
      "y": 33,
      "z": 5,
      "type": "hull_reinforced"
    },
    {
      "x": 33,
      "y": 32,
      "z": 5,
      "type": "hull_reinforced"
    },
    {
      "x": 31,
      "y": 32,
      "z": 6,
      "type": "hull_reinforced"
    },
    {
      "x": 32,
      "y": 31,
      "z": 6,
      "type": "hull_reinforced"
    },
    {
      "x": 32,
      "y": 32,
      "z": 6,
      "type": "hull_reinforced"
    },
    {
      "x": 32,
      "y": 33,
      "z": 6,
      "type": "hull_reinforced"
    },
    {
      "x": 33,
      "y": 32,
      "z": 6,
      "type": "hull_reinforced"
    },
    {
      "x": 31,
      "y": 32,
      "z": 7,
      "type": "hull_reinforced"
    },
    {
      "x": 32,
      "y": 31,
      "z": 7,
      "type": "hull_reinforced"
    },
    {
      "x": 32,
      "y": 32,
      "z": 7,
      "type": "hull_reinforced"
    },
    {
      "x": 32,
      "y": 33,
      "z": 7,
      "type": "hull_reinforced"
    },
    {
      "x": 33,
      "y": 32,
      "z": 7,
      "type": "hull_reinforced"
    },
    {
      "x": 31,
      "y": 32,
      "z": 8,
      "type": "hull_reinforced"
    },
    {
      "x": 32,
      "y": 31,
      "z": 8,
      "type": "hull_reinforced"
    },
    {
      "x": 32,
      "y": 32,
      "z": 8,
      "type": "hull_reinforced"
    },
    {
      "x": 32,
      "y": 33,
      "z": 8,
      "type": "hull_reinforced"
    },
    {
      "x": 33,
      "y": 32,
      "z": 8,
      "type": "hull_reinforced"
    },
    {
      "x": 31,
      "y": 32,
      "z": 9,
      "type": "hull_reinforced"
    },
    {
      "x": 32,
      "y": 31,
      "z": 9,
      "type": "hull_reinforced"
    },
    {
      "x": 32,
      "y": 32,
      "z": 9,
      "type": "hull_reinforced"
    },
    {
      "x": 32,
      "y": 33,
      "z": 9,
      "type": "hull_reinforced"
    },
    {
      "x": 33,
      "y": 32,
      "z": 9,
      "type": "hull_reinforced"
    },
    {
      "x": 31,
      "y": 32,
      "z": 10,
      "type": "hull_reinforced"
    },
    {
      "x": 32,
      "y": 31,
      "z": 10,
      "type": "hull_reinforced"
    },
    {
      "x": 32,
      "y": 32,
      "z": 10,
      "type": "hull_reinforced"
    },
    {
      "x": 32,
      "y": 33,
      "z": 10,
      "type": "hull_reinforced"
    },
    {
      "x": 33,
      "y": 32,
      "z": 10,
      "type": "hull_reinforced"
    },
    {
      "x": 31,
      "y": 32,
      "z": 11,
      "type": "hull_reinforced"
    },
    {
      "x": 32,
      "y": 31,
      "z": 11,
      "type": "hull_reinforced"
    },
    {
      "x": 32,
      "y": 32,
      "z": 11,
      "type": "hull_reinforced"
    },
    {
      "x": 32,
      "y": 33,
      "z": 11,
      "type": "hull_reinforced"
    },
    {
      "x": 33,
      "y": 32,
      "z": 11,
      "type": "hull_reinforced"
    },
    {
      "x": 31,
      "y": 32,
      "z": 12,
      "type": "hull_reinforced"
    },
    {
      "x": 32,
      "y": 31,
      "z": 12,
      "type": "hull_reinforced"
    },
    {
      "x": 32,
      "y": 32,
      "z": 12,
      "type": "hull_reinforced"
    },
    {
      "x": 32,
      "y": 33,
      "z": 12,
      "type": "hull_reinforced"
    },
    {
      "x": 33,
      "y": 32,
      "z": 12,
      "type": "hull_reinforced"
    },
    {
      "x": 31,
      "y": 32,
      "z": 13,
      "type": "hull_reinforced"
    },
    {
      "x": 32,
      "y": 31,
      "z": 13,
      "type": "hull_reinforced"
    },
    {
      "x": 32,
      "y": 32,
      "z": 13,
      "type": "hull_reinforced"
    },
    {
      "x": 32,
      "y": 33,
      "z": 13,
      "type": "hull_reinforced"
    },
    {
      "x": 33,
      "y": 32,
      "z": 13,
      "type": "hull_reinforced"
    },
    {
      "x": 31,
      "y": 32,
      "z": 14,
      "type": "hull_reinforced"
    },
    {
      "x": 32,
      "y": 31,
      "z": 14,
      "type": "hull_reinforced"
    },
    {
      "x": 32,
      "y": 32,
      "z": 14,
      "type": "hull_reinforced"
    },
    {
      "x": 32,
      "y": 33,
      "z": 14,
      "type": "hull_reinforced"
    },
    {
      "x": 33,
      "y": 32,
      "z": 14,
      "type": "hull_reinforced"
    },
    {
      "x": 31,
      "y": 32,
      "z": 15,
      "type": "hull_reinforced"
    },
    {
      "x": 32,
      "y": 31,
      "z": 15,
      "type": "hull_reinforced"
    },
    {
      "x": 32,
      "y": 32,
      "z": 15,
      "type": "hull_reinforced"
    },
    {
      "x": 32,
      "y": 33,
      "z": 15,
      "type": "hull_reinforced"
    },
    {
      "x": 33,
      "y": 32,
      "z": 15,
      "type": "hull_reinforced"
    },
    {
      "x": 31,
      "y": 32,
      "z": 16,
      "type": "hull_reinforced"
    },
    {
      "x": 32,
      "y": 31,
      "z": 16,
      "type": "hull_reinforced"
    },
    {
      "x": 32,
      "y": 32,
      "z": 16,
      "type": "hull_reinforced"
    },
    {
      "x": 32,
      "y": 33,
      "z": 16,
      "type": "hull_reinforced"
    },
    {
      "x": 33,
      "y": 32,
      "z": 16,
      "type": "hull_reinforced"
    },
    {
      "x": 31,
      "y": 32,
      "z": 17,
      "type": "hull_reinforced"
    },
    {
      "x": 32,
      "y": 31,
      "z": 17,
      "type": "hull_reinforced"
    },
    {
      "x": 32,
      "y": 32,
      "z": 17,
      "type": "hull_reinforced"
    },
    {
      "x": 32,
      "y": 33,
      "z": 17,
      "type": "hull_reinforced"
    },
    {
      "x": 33,
      "y": 32,
      "z": 17,
      "type": "hull_reinforced"
    },
    {
      "x": 31,
      "y": 32,
      "z": 18,
      "type": "hull_reinforced"
    },
    {
      "x": 32,
      "y": 31,
      "z": 18,
      "type": "hull_reinforced"
    },
    {
      "x": 32,
      "y": 32,
      "z": 18,
      "type": "hull_reinforced"
    },
    {
      "x": 32,
      "y": 33,
      "z": 18,
      "type": "hull_reinforced"
    },
    {
      "x": 33,
      "y": 32,
      "z": 18,
      "type": "hull_reinforced"
    },
    {
      "x": 31,
      "y": 32,
      "z": 19,
      "type": "hull_reinforced"
    },
    {
      "x": 32,
      "y": 31,
      "z": 19,
      "type": "hull_reinforced"
    },
    {
      "x": 32,
      "y": 32,
      "z": 19,
      "type": "hull_reinforced"
    },
    {
      "x": 32,
      "y": 33,
      "z": 19,
      "type": "hull_reinforced"
    },
    {
      "x": 33,
      "y": 32,
      "z": 19,
      "type": "hull_reinforced"
    },
    {
      "x": 31,
      "y": 32,
      "z": 20,
      "type": "hull_reinforced"
    },
    {
      "x": 32,
      "y": 31,
      "z": 20,
      "type": "hull_reinforced"
    },
    {
      "x": 32,
      "y": 32,
      "z": 20,
      "type": "hull_reinforced"
    },
    {
      "x": 32,
      "y": 33,
      "z": 20,
      "type": "hull_reinforced"
    },
    {
      "x": 33,
      "y": 32,
      "z": 20,
      "type": "hull_reinforced"
    },
    {
      "x": 31,
      "y": 32,
      "z": 21,
      "type": "hull_reinforced"
    },
    {
      "x": 32,
      "y": 31,
      "z": 21,
      "type": "hull_reinforced"
    },
    {
      "x": 32,
      "y": 32,
      "z": 21,
      "type": "hull_reinforced"
    },
    {
      "x": 32,
      "y": 33,
      "z": 21,
      "type": "hull_reinforced"
    },
    {
      "x": 33,
      "y": 32,
      "z": 21,
      "type": "hull_reinforced"
    },
    {
      "x": 31,
      "y": 32,
      "z": 22,
      "type": "hull_reinforced"
    },
    {
      "x": 32,
      "y": 31,
      "z": 22,
      "type": "hull_reinforced"
    },
    {
      "x": 32,
      "y": 32,
      "z": 22,
      "type": "hull_reinforced"
    },
    {
      "x": 32,
      "y": 33,
      "z": 22,
      "type": "hull_reinforced"
    },
    {
      "x": 33,
      "y": 32,
      "z": 22,
      "type": "hull_reinforced"
    },
    {
      "x": 31,
      "y": 32,
      "z": 23,
      "type": "hull_reinforced"
    },
    {
      "x": 32,
      "y": 31,
      "z": 23,
      "type": "hull_reinforced"
    },
    {
      "x": 32,
      "y": 32,
      "z": 23,
      "type": "hull_reinforced"
    },
    {
      "x": 32,
      "y": 33,
      "z": 23,
      "type": "hull_reinforced"
    },
    {
      "x": 33,
      "y": 32,
      "z": 23,
      "type": "hull_reinforced"
    },
    {
      "x": 31,
      "y": 32,
      "z": 24,
      "type": "hull_reinforced"
    },
    {
      "x": 32,
      "y": 31,
      "z": 24,
      "type": "hull_reinforced"
    },
    {
      "x": 32,
      "y": 32,
      "z": 24,
      "type": "hull_reinforced"
    },
    {
      "x": 32,
      "y": 33,
      "z": 24,
      "type": "hull_reinforced"
    },
    {
      "x": 33,
      "y": 32,
      "z": 24,
      "type": "hull_reinforced"
    },
    {
      "x": 31,
      "y": 32,
      "z": 25,
      "type": "hull_reinforced"
    },
    {
      "x": 32,
      "y": 31,
      "z": 25,
      "type": "hull_reinforced"
    },
    {
      "x": 32,
      "y": 32,
      "z": 25,
      "type": "hull_reinforced"
    },
    {
      "x": 32,
      "y": 33,
      "z": 25,
      "type": "hull_reinforced"
    },
    {
      "x": 33,
      "y": 32,
      "z": 25,
      "type": "hull_reinforced"
    },
    {
      "x": 31,
      "y": 32,
      "z": 26,
      "type": "hull_reinforced"
    },
    {
      "x": 32,
      "y": 31,
      "z": 26,
      "type": "hull_reinforced"
    },
    {
      "x": 32,
      "y": 32,
      "z": 26,
      "type": "hull_reinforced"
    },
    {
      "x": 32,
      "y": 33,
      "z": 26,
      "type": "hull_reinforced"
    },
    {
      "x": 33,
      "y": 32,
      "z": 26,
      "type": "hull_reinforced"
    },
    {
      "x": 31,
      "y": 32,
      "z": 27,
      "type": "hull_reinforced"
    },
    {
      "x": 32,
      "y": 31,
      "z": 27,
      "type": "hull_reinforced"
    },
    {
      "x": 32,
      "y": 32,
      "z": 27,
      "type": "hull_reinforced"
    },
    {
      "x": 32,
      "y": 33,
      "z": 27,
      "type": "hull_reinforced"
    },
    {
      "x": 33,
      "y": 32,
      "z": 27,
      "type": "hull_reinforced"
    },
    {
      "x": 31,
      "y": 32,
      "z": 28,
      "type": "hull_reinforced"
    },
    {
      "x": 32,
      "y": 31,
      "z": 28,
      "type": "hull_reinforced"
    },
    {
      "x": 32,
      "y": 32,
      "z": 28,
      "type": "hull_reinforced"
    },
    {
      "x": 32,
      "y": 33,
      "z": 28,
      "type": "hull_reinforced"
    },
    {
      "x": 33,
      "y": 32,
      "z": 28,
      "type": "hull_reinforced"
    },
    {
      "x": 31,
      "y": 32,
      "z": 29,
      "type": "hull_reinforced"
    },
    {
      "x": 32,
      "y": 31,
      "z": 29,
      "type": "hull_reinforced"
    },
    {
      "x": 32,
      "y": 32,
      "z": 29,
      "type": "hull_reinforced"
    },
    {
      "x": 32,
      "y": 33,
      "z": 29,
      "type": "hull_reinforced"
    },
    {
      "x": 33,
      "y": 32,
      "z": 29,
      "type": "hull_reinforced"
    },
    {
      "x": 31,
      "y": 32,
      "z": 30,
      "type": "hull_reinforced"
    },
    {
      "x": 32,
      "y": 31,
      "z": 30,
      "type": "hull_reinforced"
    },
    {
      "x": 32,
      "y": 32,
      "z": 30,
      "type": "hull_reinforced"
    },
    {
      "x": 32,
      "y": 33,
      "z": 30,
      "type": "hull_reinforced"
    },
    {
      "x": 33,
      "y": 32,
      "z": 30,
      "type": "hull_reinforced"
    },
    {
      "x": 31,
      "y": 32,
      "z": 31,
      "type": "hull_reinforced"
    },
    {
      "x": 32,
      "y": 31,
      "z": 31,
      "type": "hull_reinforced"
    },
    {
      "x": 32,
      "y": 32,
      "z": 31,
      "type": "hull_reinforced"
    },
    {
      "x": 32,
      "y": 33,
      "z": 31,
      "type": "hull_reinforced"
    },
    {
      "x": 33,
      "y": 32,
      "z": 31,
      "type": "hull_reinforced"
    },
    {
      "x": 31,
      "y": 32,
      "z": 32,
      "type": "hull_reinforced"
    },
    {
      "x": 32,
      "y": 31,
      "z": 32,
      "type": "hull_reinforced"
    },
    {
      "x": 32,
      "y": 32,
      "z": 32,
      "type": "hull_reinforced"
    },
    {
      "x": 32,
      "y": 33,
      "z": 32,
      "type": "hull_reinforced"
    },
    {
      "x": 33,
      "y": 32,
      "z": 32,
      "type": "hull_reinforced"
    },
    {
      "x": 31,
      "y": 32,
      "z": 33,
      "type": "hull_reinforced"
    },
    {
      "x": 32,
      "y": 31,
      "z": 33,
      "type": "hull_reinforced"
    },
    {
      "x": 32,
      "y": 32,
      "z": 33,
      "type": "hull_reinforced"
    },
    {
      "x": 32,
      "y": 33,
      "z": 33,
      "type": "hull_reinforced"
    },
    {
      "x": 33,
      "y": 32,
      "z": 33,
      "type": "hull_reinforced"
    },
    {
      "x": 31,
      "y": 32,
      "z": 34,
      "type": "hull_reinforced"
    },
    {
      "x": 32,
      "y": 31,
      "z": 34,
      "type": "hull_reinforced"
    },
    {
      "x": 32,
      "y": 32,
      "z": 34,
      "type": "hull_reinforced"
    },
    {
      "x": 32,
      "y": 33,
      "z": 34,
      "type": "hull_reinforced"
    },
    {
      "x": 33,
      "y": 32,
      "z": 34,
      "type": "hull_reinforced"
    },
    {
      "x": 31,
      "y": 32,
      "z": 35,
      "type": "hull_reinforced"
    },
    {
      "x": 32,
      "y": 31,
      "z": 35,
      "type": "hull_reinforced"
    },
    {
      "x": 32,
      "y": 32,
      "z": 35,
      "type": "hull_reinforced"
    },
    {
      "x": 32,
      "y": 33,
      "z": 35,
      "type": "hull_reinforced"
    },
    {
      "x": 33,
      "y": 32,
      "z": 35,
      "type": "hull_reinforced"
    },
    {
      "x": 31,
      "y": 32,
      "z": 36,
      "type": "hull_reinforced"
    },
    {
      "x": 32,
      "y": 31,
      "z": 36,
      "type": "hull_reinforced"
    },
    {
      "x": 32,
      "y": 32,
      "z": 36,
      "type": "hull_reinforced"
    },
    {
      "x": 32,
      "y": 33,
      "z": 36,
      "type": "hull_reinforced"
    },
    {
      "x": 33,
      "y": 32,
      "z": 36,
      "type": "hull_reinforced"
    },
    {
      "x": 31,
      "y": 32,
      "z": 37,
      "type": "hull_reinforced"
    },
    {
      "x": 32,
      "y": 31,
      "z": 37,
      "type": "hull_reinforced"
    },
    {
      "x": 32,
      "y": 32,
      "z": 37,
      "type": "hull_reinforced"
    },
    {
      "x": 32,
      "y": 33,
      "z": 37,
      "type": "hull_reinforced"
    },
    {
      "x": 33,
      "y": 32,
      "z": 37,
      "type": "hull_reinforced"
    },
    {
      "x": 31,
      "y": 32,
      "z": 38,
      "type": "hull_reinforced"
    },
    {
      "x": 32,
      "y": 31,
      "z": 38,
      "type": "hull_reinforced"
    },
    {
      "x": 32,
      "y": 32,
      "z": 38,
      "type": "hull_reinforced"
    },
    {
      "x": 32,
      "y": 33,
      "z": 38,
      "type": "hull_reinforced"
    },
    {
      "x": 33,
      "y": 32,
      "z": 38,
      "type": "hull_reinforced"
    },
    {
      "x": 31,
      "y": 32,
      "z": 39,
      "type": "hull_reinforced"
    },
    {
      "x": 32,
      "y": 31,
      "z": 39,
      "type": "hull_reinforced"
    },
    {
      "x": 32,
      "y": 32,
      "z": 39,
      "type": "hull_reinforced"
    },
    {
      "x": 32,
      "y": 33,
      "z": 39,
      "type": "hull_reinforced"
    },
    {
      "x": 33,
      "y": 32,
      "z": 39,
      "type": "hull_reinforced"
    },
    {
      "x": 31,
      "y": 32,
      "z": 40,
      "type": "hull_reinforced"
    },
    {
      "x": 32,
      "y": 31,
      "z": 40,
      "type": "hull_reinforced"
    },
    {
      "x": 32,
      "y": 32,
      "z": 40,
      "type": "hull_reinforced"
    },
    {
      "x": 32,
      "y": 33,
      "z": 40,
      "type": "hull_reinforced"
    },
    {
      "x": 33,
      "y": 32,
      "z": 40,
      "type": "hull_reinforced"
    },
    {
      "x": 31,
      "y": 32,
      "z": 41,
      "type": "hull_reinforced"
    },
    {
      "x": 32,
      "y": 31,
      "z": 41,
      "type": "hull_reinforced"
    },
    {
      "x": 32,
      "y": 32,
      "z": 41,
      "type": "hull_reinforced"
    },
    {
      "x": 32,
      "y": 33,
      "z": 41,
      "type": "hull_reinforced"
    },
    {
      "x": 33,
      "y": 32,
      "z": 41,
      "type": "hull_reinforced"
    },
    {
      "x": 31,
      "y": 32,
      "z": 42,
      "type": "hull_reinforced"
    },
    {
      "x": 32,
      "y": 31,
      "z": 42,
      "type": "hull_reinforced"
    },
    {
      "x": 32,
      "y": 32,
      "z": 42,
      "type": "hull_reinforced"
    },
    {
      "x": 32,
      "y": 33,
      "z": 42,
      "type": "hull_reinforced"
    },
    {
      "x": 33,
      "y": 32,
      "z": 42,
      "type": "hull_reinforced"
    },
    {
      "x": 31,
      "y": 32,
      "z": 43,
      "type": "hull_reinforced"
    },
    {
      "x": 32,
      "y": 31,
      "z": 43,
      "type": "hull_reinforced"
    },
    {
      "x": 32,
      "y": 32,
      "z": 43,
      "type": "hull_reinforced"
    },
    {
      "x": 32,
      "y": 33,
      "z": 43,
      "type": "hull_reinforced"
    },
    {
      "x": 33,
      "y": 32,
      "z": 43,
      "type": "hull_reinforced"
    },
    {
      "x": 31,
      "y": 32,
      "z": 44,
      "type": "hull_reinforced"
    },
    {
      "x": 32,
      "y": 31,
      "z": 44,
      "type": "hull_reinforced"
    },
    {
      "x": 32,
      "y": 32,
      "z": 44,
      "type": "hull_reinforced"
    },
    {
      "x": 32,
      "y": 33,
      "z": 44,
      "type": "hull_reinforced"
    },
    {
      "x": 33,
      "y": 32,
      "z": 44,
      "type": "hull_reinforced"
    },
    {
      "x": 31,
      "y": 32,
      "z": 45,
      "type": "hull_reinforced"
    },
    {
      "x": 32,
      "y": 31,
      "z": 45,
      "type": "hull_reinforced"
    },
    {
      "x": 32,
      "y": 32,
      "z": 45,
      "type": "hull_reinforced"
    },
    {
      "x": 32,
      "y": 33,
      "z": 45,
      "type": "hull_reinforced"
    },
    {
      "x": 33,
      "y": 32,
      "z": 45,
      "type": "hull_reinforced"
    },
    {
      "x": 31,
      "y": 32,
      "z": 46,
      "type": "hull_reinforced"
    },
    {
      "x": 32,
      "y": 31,
      "z": 46,
      "type": "hull_reinforced"
    },
    {
      "x": 32,
      "y": 32,
      "z": 46,
      "type": "hull_reinforced"
    },
    {
      "x": 32,
      "y": 33,
      "z": 46,
      "type": "hull_reinforced"
    },
    {
      "x": 33,
      "y": 32,
      "z": 46,
      "type": "hull_reinforced"
    },
    {
      "x": 31,
      "y": 32,
      "z": 47,
      "type": "hull_reinforced"
    },
    {
      "x": 32,
      "y": 31,
      "z": 47,
      "type": "hull_reinforced"
    },
    {
      "x": 32,
      "y": 32,
      "z": 47,
      "type": "hull_reinforced"
    },
    {
      "x": 32,
      "y": 33,
      "z": 47,
      "type": "hull_reinforced"
    },
    {
      "x": 33,
      "y": 32,
      "z": 47,
      "type": "hull_reinforced"
    },
    {
      "x": 31,
      "y": 32,
      "z": 48,
      "type": "hull_reinforced"
    },
    {
      "x": 32,
      "y": 31,
      "z": 48,
      "type": "hull_reinforced"
    },
    {
      "x": 32,
      "y": 32,
      "z": 48,
      "type": "hull_reinforced"
    },
    {
      "x": 32,
      "y": 33,
      "z": 48,
      "type": "hull_reinforced"
    },
    {
      "x": 33,
      "y": 32,
      "z": 48,
      "type": "hull_reinforced"
    },
    {
      "x": 31,
      "y": 32,
      "z": 49,
      "type": "hull_reinforced"
    },
    {
      "x": 32,
      "y": 31,
      "z": 49,
      "type": "hull_reinforced"
    },
    {
      "x": 32,
      "y": 32,
      "z": 49,
      "type": "hull_reinforced"
    },
    {
      "x": 32,
      "y": 33,
      "z": 49,
      "type": "hull_reinforced"
    },
    {
      "x": 33,
      "y": 32,
      "z": 49,
      "type": "hull_reinforced"
    },
    {
      "x": 31,
      "y": 32,
      "z": 50,
      "type": "hull_reinforced"
    },
    {
      "x": 32,
      "y": 31,
      "z": 50,
      "type": "hull_reinforced"
    },
    {
      "x": 32,
      "y": 32,
      "z": 50,
      "type": "hull_reinforced"
    },
    {
      "x": 32,
      "y": 33,
      "z": 50,
      "type": "hull_reinforced"
    },
    {
      "x": 33,
      "y": 32,
      "z": 50,
      "type": "hull_reinforced"
    },
    {
      "x": 31,
      "y": 32,
      "z": 51,
      "type": "hull_reinforced"
    },
    {
      "x": 32,
      "y": 31,
      "z": 51,
      "type": "hull_reinforced"
    },
    {
      "x": 32,
      "y": 32,
      "z": 51,
      "type": "hull_reinforced"
    },
    {
      "x": 32,
      "y": 33,
      "z": 51,
      "type": "hull_reinforced"
    },
    {
      "x": 33,
      "y": 32,
      "z": 51,
      "type": "hull_reinforced"
    },
    {
      "x": 31,
      "y": 32,
      "z": 52,
      "type": "hull_reinforced"
    },
    {
      "x": 32,
      "y": 31,
      "z": 52,
      "type": "hull_reinforced"
    },
    {
      "x": 32,
      "y": 32,
      "z": 52,
      "type": "hull_reinforced"
    },
    {
      "x": 32,
      "y": 33,
      "z": 52,
      "type": "hull_reinforced"
    },
    {
      "x": 33,
      "y": 32,
      "z": 52,
      "type": "hull_reinforced"
    },
    {
      "x": 31,
      "y": 32,
      "z": 53,
      "type": "hull_reinforced"
    },
    {
      "x": 32,
      "y": 31,
      "z": 53,
      "type": "hull_reinforced"
    },
    {
      "x": 32,
      "y": 32,
      "z": 53,
      "type": "hull_reinforced"
    },
    {
      "x": 32,
      "y": 33,
      "z": 53,
      "type": "hull_reinforced"
    },
    {
      "x": 33,
      "y": 32,
      "z": 53,
      "type": "hull_reinforced"
    },
    {
      "x": 31,
      "y": 32,
      "z": 54,
      "type": "hull_reinforced"
    },
    {
      "x": 32,
      "y": 31,
      "z": 54,
      "type": "hull_reinforced"
    },
    {
      "x": 32,
      "y": 32,
      "z": 54,
      "type": "hull_reinforced"
    },
    {
      "x": 32,
      "y": 33,
      "z": 54,
      "type": "hull_reinforced"
    },
    {
      "x": 33,
      "y": 32,
      "z": 54,
      "type": "hull_reinforced"
    },
    {
      "x": 31,
      "y": 32,
      "z": 55,
      "type": "hull_reinforced"
    },
    {
      "x": 32,
      "y": 31,
      "z": 55,
      "type": "hull_reinforced"
    },
    {
      "x": 32,
      "y": 32,
      "z": 55,
      "type": "hull_reinforced"
    },
    {
      "x": 32,
      "y": 33,
      "z": 55,
      "type": "hull_reinforced"
    },
    {
      "x": 33,
      "y": 32,
      "z": 55,
      "type": "hull_reinforced"
    },
    {
      "x": 31,
      "y": 32,
      "z": 56,
      "type": "hull_reinforced"
    },
    {
      "x": 32,
      "y": 31,
      "z": 56,
      "type": "hull_reinforced"
    },
    {
      "x": 32,
      "y": 32,
      "z": 56,
      "type": "hull_reinforced"
    },
    {
      "x": 32,
      "y": 33,
      "z": 56,
      "type": "hull_reinforced"
    },
    {
      "x": 33,
      "y": 32,
      "z": 56,
      "type": "hull_reinforced"
    },
    {
      "x": 31,
      "y": 32,
      "z": 57,
      "type": "hull_reinforced"
    },
    {
      "x": 32,
      "y": 31,
      "z": 57,
      "type": "hull_reinforced"
    },
    {
      "x": 32,
      "y": 32,
      "z": 57,
      "type": "hull_reinforced"
    },
    {
      "x": 32,
      "y": 33,
      "z": 57,
      "type": "hull_reinforced"
    },
    {
      "x": 33,
      "y": 32,
      "z": 57,
      "type": "hull_reinforced"
    },
    {
      "x": 31,
      "y": 32,
      "z": 58,
      "type": "hull_reinforced"
    },
    {
      "x": 32,
      "y": 31,
      "z": 58,
      "type": "hull_reinforced"
    },
    {
      "x": 32,
      "y": 32,
      "z": 58,
      "type": "hull_reinforced"
    },
    {
      "x": 32,
      "y": 33,
      "z": 58,
      "type": "hull_reinforced"
    },
    {
      "x": 33,
      "y": 32,
      "z": 58,
      "type": "hull_reinforced"
    },
    {
      "x": 31,
      "y": 32,
      "z": 59,
      "type": "hull_reinforced"
    },
    {
      "x": 32,
      "y": 31,
      "z": 59,
      "type": "hull_reinforced"
    },
    {
      "x": 32,
      "y": 32,
      "z": 59,
      "type": "hull_reinforced"
    },
    {
      "x": 32,
      "y": 33,
      "z": 59,
      "type": "hull_reinforced"
    },
    {
      "x": 33,
      "y": 32,
      "z": 59,
      "type": "hull_reinforced"
    },
    {
      "x": 31,
      "y": 32,
      "z": 60,
      "type": "hull_reinforced"
    },
    {
      "x": 32,
      "y": 31,
      "z": 60,
      "type": "hull_reinforced"
    },
    {
      "x": 32,
      "y": 32,
      "z": 60,
      "type": "hull_reinforced"
    },
    {
      "x": 32,
      "y": 33,
      "z": 60,
      "type": "hull_reinforced"
    },
    {
      "x": 33,
      "y": 32,
      "z": 60,
      "type": "hull_reinforced"
    },
    {
      "x": 31,
      "y": 32,
      "z": 61,
      "type": "hull_reinforced"
    },
    {
      "x": 32,
      "y": 31,
      "z": 61,
      "type": "hull_reinforced"
    },
    {
      "x": 32,
      "y": 32,
      "z": 61,
      "type": "hull_reinforced"
    },
    {
      "x": 32,
      "y": 33,
      "z": 61,
      "type": "hull_reinforced"
    },
    {
      "x": 33,
      "y": 32,
      "z": 61,
      "type": "hull_reinforced"
    },
    {
      "x": 31,
      "y": 32,
      "z": 62,
      "type": "hull_reinforced"
    },
    {
      "x": 32,
      "y": 31,
      "z": 62,
      "type": "hull_reinforced"
    },
    {
      "x": 32,
      "y": 32,
      "z": 62,
      "type": "hull_reinforced"
    },
    {
      "x": 32,
      "y": 33,
      "z": 62,
      "type": "hull_reinforced"
    },
    {
      "x": 33,
      "y": 32,
      "z": 62,
      "type": "hull_reinforced"
    },
    {
      "x": 31,
      "y": 32,
      "z": 63,
      "type": "hull_reinforced"
    },
    {
      "x": 32,
      "y": 31,
      "z": 63,
      "type": "hull_reinforced"
    },
    {
      "x": 32,
      "y": 32,
      "z": 63,
      "type": "hull_reinforced"
    },
    {
      "x": 32,
      "y": 33,
      "z": 63,
      "type": "hull_reinforced"
    },
    {
      "x": 33,
      "y": 32,
      "z": 63,
      "type": "hull_reinforced"
    },
    {
      "x": 29,
      "y": 32,
      "z": 22,
      "type": "hull_heavy"
    },
    {
      "x": 30,
      "y": 30,
      "z": 22,
      "type": "hull_heavy"
    },
    {
      "x": 30,
      "y": 31,
      "z": 22,
      "type": "hull_heavy"
    },
    {
      "x": 30,
      "y": 32,
      "z": 22,
      "type": "hull_heavy"
    },
    {
      "x": 30,
      "y": 33,
      "z": 22,
      "type": "hull_heavy"
    },
    {
      "x": 30,
      "y": 34,
      "z": 22,
      "type": "hull_heavy"
    },
    {
      "x": 31,
      "y": 30,
      "z": 22,
      "type": "hull_heavy"
    },
    {
      "x": 31,
      "y": 34,
      "z": 22,
      "type": "hull_heavy"
    },
    {
      "x": 32,
      "y": 29,
      "z": 22,
      "type": "hull_heavy"
    },
    {
      "x": 32,
      "y": 30,
      "z": 22,
      "type": "hull_heavy"
    },
    {
      "x": 32,
      "y": 34,
      "z": 22,
      "type": "hull_heavy"
    },
    {
      "x": 32,
      "y": 35,
      "z": 22,
      "type": "hull_heavy"
    },
    {
      "x": 33,
      "y": 30,
      "z": 22,
      "type": "hull_heavy"
    },
    {
      "x": 33,
      "y": 34,
      "z": 22,
      "type": "hull_heavy"
    },
    {
      "x": 34,
      "y": 30,
      "z": 22,
      "type": "hull_heavy"
    },
    {
      "x": 34,
      "y": 31,
      "z": 22,
      "type": "hull_heavy"
    },
    {
      "x": 34,
      "y": 32,
      "z": 22,
      "type": "hull_heavy"
    },
    {
      "x": 34,
      "y": 33,
      "z": 22,
      "type": "hull_heavy"
    },
    {
      "x": 34,
      "y": 34,
      "z": 22,
      "type": "hull_heavy"
    },
    {
      "x": 35,
      "y": 32,
      "z": 22,
      "type": "hull_heavy"
    },
    {
      "x": 29,
      "y": 32,
      "z": 23,
      "type": "hull_heavy"
    },
    {
      "x": 30,
      "y": 30,
      "z": 23,
      "type": "hull_heavy"
    },
    {
      "x": 30,
      "y": 31,
      "z": 23,
      "type": "hull_heavy"
    },
    {
      "x": 30,
      "y": 32,
      "z": 23,
      "type": "hull_heavy"
    },
    {
      "x": 30,
      "y": 33,
      "z": 23,
      "type": "hull_heavy"
    },
    {
      "x": 30,
      "y": 34,
      "z": 23,
      "type": "hull_heavy"
    },
    {
      "x": 31,
      "y": 30,
      "z": 23,
      "type": "hull_heavy"
    },
    {
      "x": 31,
      "y": 34,
      "z": 23,
      "type": "hull_heavy"
    },
    {
      "x": 32,
      "y": 29,
      "z": 23,
      "type": "hull_heavy"
    },
    {
      "x": 32,
      "y": 30,
      "z": 23,
      "type": "hull_heavy"
    },
    {
      "x": 32,
      "y": 34,
      "z": 23,
      "type": "hull_heavy"
    },
    {
      "x": 32,
      "y": 35,
      "z": 23,
      "type": "hull_heavy"
    },
    {
      "x": 33,
      "y": 30,
      "z": 23,
      "type": "hull_heavy"
    },
    {
      "x": 33,
      "y": 34,
      "z": 23,
      "type": "hull_heavy"
    },
    {
      "x": 34,
      "y": 30,
      "z": 23,
      "type": "hull_heavy"
    },
    {
      "x": 34,
      "y": 31,
      "z": 23,
      "type": "hull_heavy"
    },
    {
      "x": 34,
      "y": 32,
      "z": 23,
      "type": "hull_heavy"
    },
    {
      "x": 34,
      "y": 33,
      "z": 23,
      "type": "hull_heavy"
    },
    {
      "x": 34,
      "y": 34,
      "z": 23,
      "type": "hull_heavy"
    },
    {
      "x": 35,
      "y": 32,
      "z": 23,
      "type": "hull_heavy"
    },
    {
      "x": 29,
      "y": 32,
      "z": 24,
      "type": "hull_heavy"
    },
    {
      "x": 30,
      "y": 30,
      "z": 24,
      "type": "hull_heavy"
    },
    {
      "x": 30,
      "y": 31,
      "z": 24,
      "type": "hull_heavy"
    },
    {
      "x": 30,
      "y": 32,
      "z": 24,
      "type": "hull_heavy"
    },
    {
      "x": 30,
      "y": 33,
      "z": 24,
      "type": "hull_heavy"
    },
    {
      "x": 30,
      "y": 34,
      "z": 24,
      "type": "hull_heavy"
    },
    {
      "x": 31,
      "y": 30,
      "z": 24,
      "type": "hull_heavy"
    },
    {
      "x": 31,
      "y": 34,
      "z": 24,
      "type": "hull_heavy"
    },
    {
      "x": 32,
      "y": 29,
      "z": 24,
      "type": "hull_heavy"
    },
    {
      "x": 32,
      "y": 30,
      "z": 24,
      "type": "hull_heavy"
    },
    {
      "x": 32,
      "y": 34,
      "z": 24,
      "type": "hull_heavy"
    },
    {
      "x": 32,
      "y": 35,
      "z": 24,
      "type": "hull_heavy"
    },
    {
      "x": 33,
      "y": 30,
      "z": 24,
      "type": "hull_heavy"
    },
    {
      "x": 33,
      "y": 34,
      "z": 24,
      "type": "hull_heavy"
    },
    {
      "x": 34,
      "y": 30,
      "z": 24,
      "type": "hull_heavy"
    },
    {
      "x": 34,
      "y": 31,
      "z": 24,
      "type": "hull_heavy"
    },
    {
      "x": 34,
      "y": 32,
      "z": 24,
      "type": "hull_heavy"
    },
    {
      "x": 34,
      "y": 33,
      "z": 24,
      "type": "hull_heavy"
    },
    {
      "x": 34,
      "y": 34,
      "z": 24,
      "type": "hull_heavy"
    },
    {
      "x": 35,
      "y": 32,
      "z": 24,
      "type": "hull_heavy"
    },
    {
      "x": 29,
      "y": 32,
      "z": 25,
      "type": "hull_heavy"
    },
    {
      "x": 30,
      "y": 30,
      "z": 25,
      "type": "hull_heavy"
    },
    {
      "x": 30,
      "y": 31,
      "z": 25,
      "type": "hull_heavy"
    },
    {
      "x": 30,
      "y": 32,
      "z": 25,
      "type": "hull_heavy"
    },
    {
      "x": 30,
      "y": 33,
      "z": 25,
      "type": "hull_heavy"
    },
    {
      "x": 30,
      "y": 34,
      "z": 25,
      "type": "hull_heavy"
    },
    {
      "x": 31,
      "y": 30,
      "z": 25,
      "type": "hull_heavy"
    },
    {
      "x": 31,
      "y": 34,
      "z": 25,
      "type": "hull_heavy"
    },
    {
      "x": 32,
      "y": 29,
      "z": 25,
      "type": "hull_heavy"
    },
    {
      "x": 32,
      "y": 30,
      "z": 25,
      "type": "hull_heavy"
    },
    {
      "x": 32,
      "y": 34,
      "z": 25,
      "type": "hull_heavy"
    },
    {
      "x": 32,
      "y": 35,
      "z": 25,
      "type": "hull_heavy"
    },
    {
      "x": 33,
      "y": 30,
      "z": 25,
      "type": "hull_heavy"
    },
    {
      "x": 33,
      "y": 34,
      "z": 25,
      "type": "hull_heavy"
    },
    {
      "x": 34,
      "y": 30,
      "z": 25,
      "type": "hull_heavy"
    },
    {
      "x": 34,
      "y": 31,
      "z": 25,
      "type": "hull_heavy"
    },
    {
      "x": 34,
      "y": 32,
      "z": 25,
      "type": "hull_heavy"
    },
    {
      "x": 34,
      "y": 33,
      "z": 25,
      "type": "hull_heavy"
    },
    {
      "x": 34,
      "y": 34,
      "z": 25,
      "type": "hull_heavy"
    },
    {
      "x": 35,
      "y": 32,
      "z": 25,
      "type": "hull_heavy"
    },
    {
      "x": 29,
      "y": 32,
      "z": 26,
      "type": "hull_heavy"
    },
    {
      "x": 30,
      "y": 30,
      "z": 26,
      "type": "hull_heavy"
    },
    {
      "x": 30,
      "y": 31,
      "z": 26,
      "type": "hull_heavy"
    },
    {
      "x": 30,
      "y": 32,
      "z": 26,
      "type": "hull_heavy"
    },
    {
      "x": 30,
      "y": 33,
      "z": 26,
      "type": "hull_heavy"
    },
    {
      "x": 30,
      "y": 34,
      "z": 26,
      "type": "hull_heavy"
    },
    {
      "x": 31,
      "y": 30,
      "z": 26,
      "type": "hull_heavy"
    },
    {
      "x": 31,
      "y": 34,
      "z": 26,
      "type": "hull_heavy"
    },
    {
      "x": 32,
      "y": 29,
      "z": 26,
      "type": "hull_heavy"
    },
    {
      "x": 32,
      "y": 30,
      "z": 26,
      "type": "hull_heavy"
    },
    {
      "x": 32,
      "y": 34,
      "z": 26,
      "type": "hull_heavy"
    },
    {
      "x": 32,
      "y": 35,
      "z": 26,
      "type": "hull_heavy"
    },
    {
      "x": 33,
      "y": 30,
      "z": 26,
      "type": "hull_heavy"
    },
    {
      "x": 33,
      "y": 34,
      "z": 26,
      "type": "hull_heavy"
    },
    {
      "x": 34,
      "y": 30,
      "z": 26,
      "type": "hull_heavy"
    },
    {
      "x": 34,
      "y": 31,
      "z": 26,
      "type": "hull_heavy"
    },
    {
      "x": 34,
      "y": 32,
      "z": 26,
      "type": "hull_heavy"
    },
    {
      "x": 34,
      "y": 33,
      "z": 26,
      "type": "hull_heavy"
    },
    {
      "x": 34,
      "y": 34,
      "z": 26,
      "type": "hull_heavy"
    },
    {
      "x": 35,
      "y": 32,
      "z": 26,
      "type": "hull_heavy"
    },
    {
      "x": 29,
      "y": 32,
      "z": 27,
      "type": "hull_heavy"
    },
    {
      "x": 30,
      "y": 30,
      "z": 27,
      "type": "hull_heavy"
    },
    {
      "x": 30,
      "y": 31,
      "z": 27,
      "type": "hull_heavy"
    },
    {
      "x": 30,
      "y": 32,
      "z": 27,
      "type": "hull_heavy"
    },
    {
      "x": 30,
      "y": 33,
      "z": 27,
      "type": "hull_heavy"
    },
    {
      "x": 30,
      "y": 34,
      "z": 27,
      "type": "hull_heavy"
    },
    {
      "x": 31,
      "y": 30,
      "z": 27,
      "type": "hull_heavy"
    },
    {
      "x": 31,
      "y": 34,
      "z": 27,
      "type": "hull_heavy"
    },
    {
      "x": 32,
      "y": 29,
      "z": 27,
      "type": "hull_heavy"
    },
    {
      "x": 32,
      "y": 30,
      "z": 27,
      "type": "hull_heavy"
    },
    {
      "x": 32,
      "y": 34,
      "z": 27,
      "type": "hull_heavy"
    },
    {
      "x": 32,
      "y": 35,
      "z": 27,
      "type": "hull_heavy"
    },
    {
      "x": 33,
      "y": 30,
      "z": 27,
      "type": "hull_heavy"
    },
    {
      "x": 33,
      "y": 34,
      "z": 27,
      "type": "hull_heavy"
    },
    {
      "x": 34,
      "y": 30,
      "z": 27,
      "type": "hull_heavy"
    },
    {
      "x": 34,
      "y": 31,
      "z": 27,
      "type": "hull_heavy"
    },
    {
      "x": 34,
      "y": 32,
      "z": 27,
      "type": "hull_heavy"
    },
    {
      "x": 34,
      "y": 33,
      "z": 27,
      "type": "hull_heavy"
    },
    {
      "x": 34,
      "y": 34,
      "z": 27,
      "type": "hull_heavy"
    },
    {
      "x": 35,
      "y": 32,
      "z": 27,
      "type": "hull_heavy"
    },
    {
      "x": 29,
      "y": 32,
      "z": 28,
      "type": "hull_heavy"
    },
    {
      "x": 30,
      "y": 30,
      "z": 28,
      "type": "hull_heavy"
    },
    {
      "x": 30,
      "y": 31,
      "z": 28,
      "type": "hull_heavy"
    },
    {
      "x": 30,
      "y": 32,
      "z": 28,
      "type": "hull_heavy"
    },
    {
      "x": 30,
      "y": 33,
      "z": 28,
      "type": "hull_heavy"
    },
    {
      "x": 30,
      "y": 34,
      "z": 28,
      "type": "hull_heavy"
    },
    {
      "x": 31,
      "y": 30,
      "z": 28,
      "type": "hull_heavy"
    },
    {
      "x": 31,
      "y": 34,
      "z": 28,
      "type": "hull_heavy"
    },
    {
      "x": 32,
      "y": 29,
      "z": 28,
      "type": "hull_heavy"
    },
    {
      "x": 32,
      "y": 30,
      "z": 28,
      "type": "hull_heavy"
    },
    {
      "x": 32,
      "y": 34,
      "z": 28,
      "type": "hull_heavy"
    },
    {
      "x": 32,
      "y": 35,
      "z": 28,
      "type": "hull_heavy"
    },
    {
      "x": 33,
      "y": 30,
      "z": 28,
      "type": "hull_heavy"
    },
    {
      "x": 33,
      "y": 34,
      "z": 28,
      "type": "hull_heavy"
    },
    {
      "x": 34,
      "y": 30,
      "z": 28,
      "type": "hull_heavy"
    },
    {
      "x": 34,
      "y": 31,
      "z": 28,
      "type": "hull_heavy"
    },
    {
      "x": 34,
      "y": 32,
      "z": 28,
      "type": "hull_heavy"
    },
    {
      "x": 34,
      "y": 33,
      "z": 28,
      "type": "hull_heavy"
    },
    {
      "x": 34,
      "y": 34,
      "z": 28,
      "type": "hull_heavy"
    },
    {
      "x": 35,
      "y": 32,
      "z": 28,
      "type": "hull_heavy"
    },
    {
      "x": 29,
      "y": 32,
      "z": 29,
      "type": "hull_heavy"
    },
    {
      "x": 30,
      "y": 30,
      "z": 29,
      "type": "hull_heavy"
    },
    {
      "x": 30,
      "y": 31,
      "z": 29,
      "type": "hull_heavy"
    },
    {
      "x": 30,
      "y": 32,
      "z": 29,
      "type": "hull_heavy"
    },
    {
      "x": 30,
      "y": 33,
      "z": 29,
      "type": "hull_heavy"
    },
    {
      "x": 30,
      "y": 34,
      "z": 29,
      "type": "hull_heavy"
    },
    {
      "x": 31,
      "y": 30,
      "z": 29,
      "type": "hull_heavy"
    },
    {
      "x": 31,
      "y": 34,
      "z": 29,
      "type": "hull_heavy"
    },
    {
      "x": 32,
      "y": 29,
      "z": 29,
      "type": "hull_heavy"
    },
    {
      "x": 32,
      "y": 30,
      "z": 29,
      "type": "hull_heavy"
    },
    {
      "x": 32,
      "y": 34,
      "z": 29,
      "type": "hull_heavy"
    },
    {
      "x": 32,
      "y": 35,
      "z": 29,
      "type": "hull_heavy"
    },
    {
      "x": 33,
      "y": 30,
      "z": 29,
      "type": "hull_heavy"
    },
    {
      "x": 33,
      "y": 34,
      "z": 29,
      "type": "hull_heavy"
    },
    {
      "x": 34,
      "y": 30,
      "z": 29,
      "type": "hull_heavy"
    },
    {
      "x": 34,
      "y": 31,
      "z": 29,
      "type": "hull_heavy"
    },
    {
      "x": 34,
      "y": 32,
      "z": 29,
      "type": "hull_heavy"
    },
    {
      "x": 34,
      "y": 33,
      "z": 29,
      "type": "hull_heavy"
    },
    {
      "x": 34,
      "y": 34,
      "z": 29,
      "type": "hull_heavy"
    },
    {
      "x": 35,
      "y": 32,
      "z": 29,
      "type": "hull_heavy"
    },
    {
      "x": 29,
      "y": 32,
      "z": 30,
      "type": "hull_heavy"
    },
    {
      "x": 30,
      "y": 30,
      "z": 30,
      "type": "hull_heavy"
    },
    {
      "x": 30,
      "y": 31,
      "z": 30,
      "type": "hull_heavy"
    },
    {
      "x": 30,
      "y": 32,
      "z": 30,
      "type": "hull_heavy"
    },
    {
      "x": 30,
      "y": 33,
      "z": 30,
      "type": "hull_heavy"
    },
    {
      "x": 30,
      "y": 34,
      "z": 30,
      "type": "hull_heavy"
    },
    {
      "x": 31,
      "y": 30,
      "z": 30,
      "type": "hull_heavy"
    },
    {
      "x": 31,
      "y": 34,
      "z": 30,
      "type": "hull_heavy"
    },
    {
      "x": 32,
      "y": 29,
      "z": 30,
      "type": "hull_heavy"
    },
    {
      "x": 32,
      "y": 30,
      "z": 30,
      "type": "hull_heavy"
    },
    {
      "x": 32,
      "y": 34,
      "z": 30,
      "type": "hull_heavy"
    },
    {
      "x": 32,
      "y": 35,
      "z": 30,
      "type": "hull_heavy"
    },
    {
      "x": 33,
      "y": 30,
      "z": 30,
      "type": "hull_heavy"
    },
    {
      "x": 33,
      "y": 34,
      "z": 30,
      "type": "hull_heavy"
    },
    {
      "x": 34,
      "y": 30,
      "z": 30,
      "type": "hull_heavy"
    },
    {
      "x": 34,
      "y": 31,
      "z": 30,
      "type": "hull_heavy"
    },
    {
      "x": 34,
      "y": 32,
      "z": 30,
      "type": "hull_heavy"
    },
    {
      "x": 34,
      "y": 33,
      "z": 30,
      "type": "hull_heavy"
    },
    {
      "x": 34,
      "y": 34,
      "z": 30,
      "type": "hull_heavy"
    },
    {
      "x": 35,
      "y": 32,
      "z": 30,
      "type": "hull_heavy"
    },
    {
      "x": 29,
      "y": 32,
      "z": 31,
      "type": "hull_heavy"
    },
    {
      "x": 30,
      "y": 30,
      "z": 31,
      "type": "hull_heavy"
    },
    {
      "x": 30,
      "y": 31,
      "z": 31,
      "type": "hull_heavy"
    },
    {
      "x": 30,
      "y": 32,
      "z": 31,
      "type": "hull_heavy"
    },
    {
      "x": 30,
      "y": 33,
      "z": 31,
      "type": "hull_heavy"
    },
    {
      "x": 30,
      "y": 34,
      "z": 31,
      "type": "hull_heavy"
    },
    {
      "x": 31,
      "y": 30,
      "z": 31,
      "type": "hull_heavy"
    },
    {
      "x": 31,
      "y": 34,
      "z": 31,
      "type": "hull_heavy"
    },
    {
      "x": 32,
      "y": 29,
      "z": 31,
      "type": "hull_heavy"
    },
    {
      "x": 32,
      "y": 30,
      "z": 31,
      "type": "hull_heavy"
    },
    {
      "x": 32,
      "y": 34,
      "z": 31,
      "type": "hull_heavy"
    },
    {
      "x": 32,
      "y": 35,
      "z": 31,
      "type": "hull_heavy"
    },
    {
      "x": 33,
      "y": 30,
      "z": 31,
      "type": "hull_heavy"
    },
    {
      "x": 33,
      "y": 34,
      "z": 31,
      "type": "hull_heavy"
    },
    {
      "x": 34,
      "y": 30,
      "z": 31,
      "type": "hull_heavy"
    },
    {
      "x": 34,
      "y": 31,
      "z": 31,
      "type": "hull_heavy"
    },
    {
      "x": 34,
      "y": 32,
      "z": 31,
      "type": "hull_heavy"
    },
    {
      "x": 34,
      "y": 33,
      "z": 31,
      "type": "hull_heavy"
    },
    {
      "x": 34,
      "y": 34,
      "z": 31,
      "type": "hull_heavy"
    },
    {
      "x": 35,
      "y": 32,
      "z": 31,
      "type": "hull_heavy"
    },
    {
      "x": 29,
      "y": 32,
      "z": 32,
      "type": "hull_heavy"
    },
    {
      "x": 30,
      "y": 30,
      "z": 32,
      "type": "hull_heavy"
    },
    {
      "x": 30,
      "y": 31,
      "z": 32,
      "type": "hull_heavy"
    },
    {
      "x": 30,
      "y": 32,
      "z": 32,
      "type": "hull_heavy"
    },
    {
      "x": 30,
      "y": 33,
      "z": 32,
      "type": "hull_heavy"
    },
    {
      "x": 30,
      "y": 34,
      "z": 32,
      "type": "hull_heavy"
    },
    {
      "x": 31,
      "y": 30,
      "z": 32,
      "type": "hull_heavy"
    },
    {
      "x": 31,
      "y": 34,
      "z": 32,
      "type": "hull_heavy"
    },
    {
      "x": 32,
      "y": 29,
      "z": 32,
      "type": "hull_heavy"
    },
    {
      "x": 32,
      "y": 30,
      "z": 32,
      "type": "hull_heavy"
    },
    {
      "x": 32,
      "y": 34,
      "z": 32,
      "type": "hull_heavy"
    },
    {
      "x": 32,
      "y": 35,
      "z": 32,
      "type": "hull_heavy"
    },
    {
      "x": 33,
      "y": 30,
      "z": 32,
      "type": "hull_heavy"
    },
    {
      "x": 33,
      "y": 34,
      "z": 32,
      "type": "hull_heavy"
    },
    {
      "x": 34,
      "y": 30,
      "z": 32,
      "type": "hull_heavy"
    },
    {
      "x": 34,
      "y": 31,
      "z": 32,
      "type": "hull_heavy"
    },
    {
      "x": 34,
      "y": 32,
      "z": 32,
      "type": "hull_heavy"
    },
    {
      "x": 34,
      "y": 33,
      "z": 32,
      "type": "hull_heavy"
    },
    {
      "x": 34,
      "y": 34,
      "z": 32,
      "type": "hull_heavy"
    },
    {
      "x": 35,
      "y": 32,
      "z": 32,
      "type": "hull_heavy"
    },
    {
      "x": 29,
      "y": 32,
      "z": 33,
      "type": "hull_heavy"
    },
    {
      "x": 30,
      "y": 30,
      "z": 33,
      "type": "hull_heavy"
    },
    {
      "x": 30,
      "y": 31,
      "z": 33,
      "type": "hull_heavy"
    },
    {
      "x": 30,
      "y": 32,
      "z": 33,
      "type": "hull_heavy"
    },
    {
      "x": 30,
      "y": 33,
      "z": 33,
      "type": "hull_heavy"
    },
    {
      "x": 30,
      "y": 34,
      "z": 33,
      "type": "hull_heavy"
    },
    {
      "x": 31,
      "y": 30,
      "z": 33,
      "type": "hull_heavy"
    },
    {
      "x": 31,
      "y": 34,
      "z": 33,
      "type": "hull_heavy"
    },
    {
      "x": 32,
      "y": 29,
      "z": 33,
      "type": "hull_heavy"
    },
    {
      "x": 32,
      "y": 30,
      "z": 33,
      "type": "hull_heavy"
    },
    {
      "x": 32,
      "y": 34,
      "z": 33,
      "type": "hull_heavy"
    },
    {
      "x": 32,
      "y": 35,
      "z": 33,
      "type": "hull_heavy"
    },
    {
      "x": 33,
      "y": 30,
      "z": 33,
      "type": "hull_heavy"
    },
    {
      "x": 33,
      "y": 34,
      "z": 33,
      "type": "hull_heavy"
    },
    {
      "x": 34,
      "y": 30,
      "z": 33,
      "type": "hull_heavy"
    },
    {
      "x": 34,
      "y": 31,
      "z": 33,
      "type": "hull_heavy"
    },
    {
      "x": 34,
      "y": 32,
      "z": 33,
      "type": "hull_heavy"
    },
    {
      "x": 34,
      "y": 33,
      "z": 33,
      "type": "hull_heavy"
    },
    {
      "x": 34,
      "y": 34,
      "z": 33,
      "type": "hull_heavy"
    },
    {
      "x": 35,
      "y": 32,
      "z": 33,
      "type": "hull_heavy"
    },
    {
      "x": 29,
      "y": 32,
      "z": 34,
      "type": "hull_heavy"
    },
    {
      "x": 30,
      "y": 30,
      "z": 34,
      "type": "hull_heavy"
    },
    {
      "x": 30,
      "y": 31,
      "z": 34,
      "type": "hull_heavy"
    },
    {
      "x": 30,
      "y": 32,
      "z": 34,
      "type": "hull_heavy"
    },
    {
      "x": 30,
      "y": 33,
      "z": 34,
      "type": "hull_heavy"
    },
    {
      "x": 30,
      "y": 34,
      "z": 34,
      "type": "hull_heavy"
    },
    {
      "x": 31,
      "y": 30,
      "z": 34,
      "type": "hull_heavy"
    },
    {
      "x": 31,
      "y": 34,
      "z": 34,
      "type": "hull_heavy"
    },
    {
      "x": 32,
      "y": 29,
      "z": 34,
      "type": "hull_heavy"
    },
    {
      "x": 32,
      "y": 30,
      "z": 34,
      "type": "hull_heavy"
    },
    {
      "x": 32,
      "y": 34,
      "z": 34,
      "type": "hull_heavy"
    },
    {
      "x": 32,
      "y": 35,
      "z": 34,
      "type": "hull_heavy"
    },
    {
      "x": 33,
      "y": 30,
      "z": 34,
      "type": "hull_heavy"
    },
    {
      "x": 33,
      "y": 34,
      "z": 34,
      "type": "hull_heavy"
    },
    {
      "x": 34,
      "y": 30,
      "z": 34,
      "type": "hull_heavy"
    },
    {
      "x": 34,
      "y": 31,
      "z": 34,
      "type": "hull_heavy"
    },
    {
      "x": 34,
      "y": 32,
      "z": 34,
      "type": "hull_heavy"
    },
    {
      "x": 34,
      "y": 33,
      "z": 34,
      "type": "hull_heavy"
    },
    {
      "x": 34,
      "y": 34,
      "z": 34,
      "type": "hull_heavy"
    },
    {
      "x": 35,
      "y": 32,
      "z": 34,
      "type": "hull_heavy"
    },
    {
      "x": 29,
      "y": 32,
      "z": 35,
      "type": "hull_heavy"
    },
    {
      "x": 30,
      "y": 30,
      "z": 35,
      "type": "hull_heavy"
    },
    {
      "x": 30,
      "y": 31,
      "z": 35,
      "type": "hull_heavy"
    },
    {
      "x": 30,
      "y": 32,
      "z": 35,
      "type": "hull_heavy"
    },
    {
      "x": 30,
      "y": 33,
      "z": 35,
      "type": "hull_heavy"
    },
    {
      "x": 30,
      "y": 34,
      "z": 35,
      "type": "hull_heavy"
    },
    {
      "x": 31,
      "y": 30,
      "z": 35,
      "type": "hull_heavy"
    },
    {
      "x": 31,
      "y": 34,
      "z": 35,
      "type": "hull_heavy"
    },
    {
      "x": 32,
      "y": 29,
      "z": 35,
      "type": "hull_heavy"
    },
    {
      "x": 32,
      "y": 30,
      "z": 35,
      "type": "hull_heavy"
    },
    {
      "x": 32,
      "y": 34,
      "z": 35,
      "type": "hull_heavy"
    },
    {
      "x": 32,
      "y": 35,
      "z": 35,
      "type": "hull_heavy"
    },
    {
      "x": 33,
      "y": 30,
      "z": 35,
      "type": "hull_heavy"
    },
    {
      "x": 33,
      "y": 34,
      "z": 35,
      "type": "hull_heavy"
    },
    {
      "x": 34,
      "y": 30,
      "z": 35,
      "type": "hull_heavy"
    },
    {
      "x": 34,
      "y": 31,
      "z": 35,
      "type": "hull_heavy"
    },
    {
      "x": 34,
      "y": 32,
      "z": 35,
      "type": "hull_heavy"
    },
    {
      "x": 34,
      "y": 33,
      "z": 35,
      "type": "hull_heavy"
    },
    {
      "x": 34,
      "y": 34,
      "z": 35,
      "type": "hull_heavy"
    },
    {
      "x": 35,
      "y": 32,
      "z": 35,
      "type": "hull_heavy"
    },
    {
      "x": 29,
      "y": 32,
      "z": 36,
      "type": "hull_heavy"
    },
    {
      "x": 30,
      "y": 30,
      "z": 36,
      "type": "hull_heavy"
    },
    {
      "x": 30,
      "y": 31,
      "z": 36,
      "type": "hull_heavy"
    },
    {
      "x": 30,
      "y": 32,
      "z": 36,
      "type": "hull_heavy"
    },
    {
      "x": 30,
      "y": 33,
      "z": 36,
      "type": "hull_heavy"
    },
    {
      "x": 30,
      "y": 34,
      "z": 36,
      "type": "hull_heavy"
    },
    {
      "x": 31,
      "y": 30,
      "z": 36,
      "type": "hull_heavy"
    },
    {
      "x": 31,
      "y": 34,
      "z": 36,
      "type": "hull_heavy"
    },
    {
      "x": 32,
      "y": 29,
      "z": 36,
      "type": "hull_heavy"
    },
    {
      "x": 32,
      "y": 30,
      "z": 36,
      "type": "hull_heavy"
    },
    {
      "x": 32,
      "y": 34,
      "z": 36,
      "type": "hull_heavy"
    },
    {
      "x": 32,
      "y": 35,
      "z": 36,
      "type": "hull_heavy"
    },
    {
      "x": 33,
      "y": 30,
      "z": 36,
      "type": "hull_heavy"
    },
    {
      "x": 33,
      "y": 34,
      "z": 36,
      "type": "hull_heavy"
    },
    {
      "x": 34,
      "y": 30,
      "z": 36,
      "type": "hull_heavy"
    },
    {
      "x": 34,
      "y": 31,
      "z": 36,
      "type": "hull_heavy"
    },
    {
      "x": 34,
      "y": 32,
      "z": 36,
      "type": "hull_heavy"
    },
    {
      "x": 34,
      "y": 33,
      "z": 36,
      "type": "hull_heavy"
    },
    {
      "x": 34,
      "y": 34,
      "z": 36,
      "type": "hull_heavy"
    },
    {
      "x": 35,
      "y": 32,
      "z": 36,
      "type": "hull_heavy"
    },
    {
      "x": 29,
      "y": 32,
      "z": 37,
      "type": "hull_heavy"
    },
    {
      "x": 30,
      "y": 30,
      "z": 37,
      "type": "hull_heavy"
    },
    {
      "x": 30,
      "y": 31,
      "z": 37,
      "type": "hull_heavy"
    },
    {
      "x": 30,
      "y": 32,
      "z": 37,
      "type": "hull_heavy"
    },
    {
      "x": 30,
      "y": 33,
      "z": 37,
      "type": "hull_heavy"
    },
    {
      "x": 30,
      "y": 34,
      "z": 37,
      "type": "hull_heavy"
    },
    {
      "x": 31,
      "y": 30,
      "z": 37,
      "type": "hull_heavy"
    },
    {
      "x": 31,
      "y": 34,
      "z": 37,
      "type": "hull_heavy"
    },
    {
      "x": 32,
      "y": 29,
      "z": 37,
      "type": "hull_heavy"
    },
    {
      "x": 32,
      "y": 30,
      "z": 37,
      "type": "hull_heavy"
    },
    {
      "x": 32,
      "y": 34,
      "z": 37,
      "type": "hull_heavy"
    },
    {
      "x": 32,
      "y": 35,
      "z": 37,
      "type": "hull_heavy"
    },
    {
      "x": 33,
      "y": 30,
      "z": 37,
      "type": "hull_heavy"
    },
    {
      "x": 33,
      "y": 34,
      "z": 37,
      "type": "hull_heavy"
    },
    {
      "x": 34,
      "y": 30,
      "z": 37,
      "type": "hull_heavy"
    },
    {
      "x": 34,
      "y": 31,
      "z": 37,
      "type": "hull_heavy"
    },
    {
      "x": 34,
      "y": 32,
      "z": 37,
      "type": "hull_heavy"
    },
    {
      "x": 34,
      "y": 33,
      "z": 37,
      "type": "hull_heavy"
    },
    {
      "x": 34,
      "y": 34,
      "z": 37,
      "type": "hull_heavy"
    },
    {
      "x": 35,
      "y": 32,
      "z": 37,
      "type": "hull_heavy"
    },
    {
      "x": 29,
      "y": 32,
      "z": 38,
      "type": "hull_heavy"
    },
    {
      "x": 30,
      "y": 30,
      "z": 38,
      "type": "hull_heavy"
    },
    {
      "x": 30,
      "y": 31,
      "z": 38,
      "type": "hull_heavy"
    },
    {
      "x": 30,
      "y": 32,
      "z": 38,
      "type": "hull_heavy"
    },
    {
      "x": 30,
      "y": 33,
      "z": 38,
      "type": "hull_heavy"
    },
    {
      "x": 30,
      "y": 34,
      "z": 38,
      "type": "hull_heavy"
    },
    {
      "x": 31,
      "y": 30,
      "z": 38,
      "type": "hull_heavy"
    },
    {
      "x": 31,
      "y": 34,
      "z": 38,
      "type": "hull_heavy"
    },
    {
      "x": 32,
      "y": 29,
      "z": 38,
      "type": "hull_heavy"
    },
    {
      "x": 32,
      "y": 30,
      "z": 38,
      "type": "hull_heavy"
    },
    {
      "x": 32,
      "y": 34,
      "z": 38,
      "type": "hull_heavy"
    },
    {
      "x": 32,
      "y": 35,
      "z": 38,
      "type": "hull_heavy"
    },
    {
      "x": 33,
      "y": 30,
      "z": 38,
      "type": "hull_heavy"
    },
    {
      "x": 33,
      "y": 34,
      "z": 38,
      "type": "hull_heavy"
    },
    {
      "x": 34,
      "y": 30,
      "z": 38,
      "type": "hull_heavy"
    },
    {
      "x": 34,
      "y": 31,
      "z": 38,
      "type": "hull_heavy"
    },
    {
      "x": 34,
      "y": 32,
      "z": 38,
      "type": "hull_heavy"
    },
    {
      "x": 34,
      "y": 33,
      "z": 38,
      "type": "hull_heavy"
    },
    {
      "x": 34,
      "y": 34,
      "z": 38,
      "type": "hull_heavy"
    },
    {
      "x": 35,
      "y": 32,
      "z": 38,
      "type": "hull_heavy"
    },
    {
      "x": 29,
      "y": 32,
      "z": 39,
      "type": "hull_heavy"
    },
    {
      "x": 30,
      "y": 30,
      "z": 39,
      "type": "hull_heavy"
    },
    {
      "x": 30,
      "y": 31,
      "z": 39,
      "type": "hull_heavy"
    },
    {
      "x": 30,
      "y": 32,
      "z": 39,
      "type": "hull_heavy"
    },
    {
      "x": 30,
      "y": 33,
      "z": 39,
      "type": "hull_heavy"
    },
    {
      "x": 30,
      "y": 34,
      "z": 39,
      "type": "hull_heavy"
    },
    {
      "x": 31,
      "y": 30,
      "z": 39,
      "type": "hull_heavy"
    },
    {
      "x": 31,
      "y": 34,
      "z": 39,
      "type": "hull_heavy"
    },
    {
      "x": 32,
      "y": 29,
      "z": 39,
      "type": "hull_heavy"
    },
    {
      "x": 32,
      "y": 30,
      "z": 39,
      "type": "hull_heavy"
    },
    {
      "x": 32,
      "y": 34,
      "z": 39,
      "type": "hull_heavy"
    },
    {
      "x": 32,
      "y": 35,
      "z": 39,
      "type": "hull_heavy"
    },
    {
      "x": 33,
      "y": 30,
      "z": 39,
      "type": "hull_heavy"
    },
    {
      "x": 33,
      "y": 34,
      "z": 39,
      "type": "hull_heavy"
    },
    {
      "x": 34,
      "y": 30,
      "z": 39,
      "type": "hull_heavy"
    },
    {
      "x": 34,
      "y": 31,
      "z": 39,
      "type": "hull_heavy"
    },
    {
      "x": 34,
      "y": 32,
      "z": 39,
      "type": "hull_heavy"
    },
    {
      "x": 34,
      "y": 33,
      "z": 39,
      "type": "hull_heavy"
    },
    {
      "x": 34,
      "y": 34,
      "z": 39,
      "type": "hull_heavy"
    },
    {
      "x": 35,
      "y": 32,
      "z": 39,
      "type": "hull_heavy"
    },
    {
      "x": 29,
      "y": 32,
      "z": 40,
      "type": "hull_heavy"
    },
    {
      "x": 30,
      "y": 30,
      "z": 40,
      "type": "hull_heavy"
    },
    {
      "x": 30,
      "y": 31,
      "z": 40,
      "type": "hull_heavy"
    },
    {
      "x": 30,
      "y": 32,
      "z": 40,
      "type": "hull_heavy"
    },
    {
      "x": 30,
      "y": 33,
      "z": 40,
      "type": "hull_heavy"
    },
    {
      "x": 30,
      "y": 34,
      "z": 40,
      "type": "hull_heavy"
    },
    {
      "x": 31,
      "y": 30,
      "z": 40,
      "type": "hull_heavy"
    },
    {
      "x": 31,
      "y": 34,
      "z": 40,
      "type": "hull_heavy"
    },
    {
      "x": 32,
      "y": 29,
      "z": 40,
      "type": "hull_heavy"
    },
    {
      "x": 32,
      "y": 30,
      "z": 40,
      "type": "hull_heavy"
    },
    {
      "x": 32,
      "y": 34,
      "z": 40,
      "type": "hull_heavy"
    },
    {
      "x": 32,
      "y": 35,
      "z": 40,
      "type": "hull_heavy"
    },
    {
      "x": 33,
      "y": 30,
      "z": 40,
      "type": "hull_heavy"
    },
    {
      "x": 33,
      "y": 34,
      "z": 40,
      "type": "hull_heavy"
    },
    {
      "x": 34,
      "y": 30,
      "z": 40,
      "type": "hull_heavy"
    },
    {
      "x": 34,
      "y": 31,
      "z": 40,
      "type": "hull_heavy"
    },
    {
      "x": 34,
      "y": 32,
      "z": 40,
      "type": "hull_heavy"
    },
    {
      "x": 34,
      "y": 33,
      "z": 40,
      "type": "hull_heavy"
    },
    {
      "x": 34,
      "y": 34,
      "z": 40,
      "type": "hull_heavy"
    },
    {
      "x": 35,
      "y": 32,
      "z": 40,
      "type": "hull_heavy"
    },
    {
      "x": 29,
      "y": 32,
      "z": 41,
      "type": "hull_heavy"
    },
    {
      "x": 30,
      "y": 30,
      "z": 41,
      "type": "hull_heavy"
    },
    {
      "x": 30,
      "y": 31,
      "z": 41,
      "type": "hull_heavy"
    },
    {
      "x": 30,
      "y": 32,
      "z": 41,
      "type": "hull_heavy"
    },
    {
      "x": 30,
      "y": 33,
      "z": 41,
      "type": "hull_heavy"
    },
    {
      "x": 30,
      "y": 34,
      "z": 41,
      "type": "hull_heavy"
    },
    {
      "x": 31,
      "y": 30,
      "z": 41,
      "type": "hull_heavy"
    },
    {
      "x": 31,
      "y": 34,
      "z": 41,
      "type": "hull_heavy"
    },
    {
      "x": 32,
      "y": 29,
      "z": 41,
      "type": "hull_heavy"
    },
    {
      "x": 32,
      "y": 30,
      "z": 41,
      "type": "hull_heavy"
    },
    {
      "x": 32,
      "y": 34,
      "z": 41,
      "type": "hull_heavy"
    },
    {
      "x": 32,
      "y": 35,
      "z": 41,
      "type": "hull_heavy"
    },
    {
      "x": 33,
      "y": 30,
      "z": 41,
      "type": "hull_heavy"
    },
    {
      "x": 33,
      "y": 34,
      "z": 41,
      "type": "hull_heavy"
    },
    {
      "x": 34,
      "y": 30,
      "z": 41,
      "type": "hull_heavy"
    },
    {
      "x": 34,
      "y": 31,
      "z": 41,
      "type": "hull_heavy"
    },
    {
      "x": 34,
      "y": 32,
      "z": 41,
      "type": "hull_heavy"
    },
    {
      "x": 34,
      "y": 33,
      "z": 41,
      "type": "hull_heavy"
    },
    {
      "x": 34,
      "y": 34,
      "z": 41,
      "type": "hull_heavy"
    },
    {
      "x": 35,
      "y": 32,
      "z": 41,
      "type": "hull_heavy"
    },
    {
      "x": 29,
      "y": 32,
      "z": 42,
      "type": "hull_heavy"
    },
    {
      "x": 30,
      "y": 30,
      "z": 42,
      "type": "hull_heavy"
    },
    {
      "x": 30,
      "y": 31,
      "z": 42,
      "type": "hull_heavy"
    },
    {
      "x": 30,
      "y": 32,
      "z": 42,
      "type": "hull_heavy"
    },
    {
      "x": 30,
      "y": 33,
      "z": 42,
      "type": "hull_heavy"
    },
    {
      "x": 30,
      "y": 34,
      "z": 42,
      "type": "hull_heavy"
    },
    {
      "x": 31,
      "y": 30,
      "z": 42,
      "type": "hull_heavy"
    },
    {
      "x": 31,
      "y": 34,
      "z": 42,
      "type": "hull_heavy"
    },
    {
      "x": 32,
      "y": 29,
      "z": 42,
      "type": "hull_heavy"
    },
    {
      "x": 32,
      "y": 30,
      "z": 42,
      "type": "hull_heavy"
    },
    {
      "x": 32,
      "y": 34,
      "z": 42,
      "type": "hull_heavy"
    },
    {
      "x": 32,
      "y": 35,
      "z": 42,
      "type": "hull_heavy"
    },
    {
      "x": 33,
      "y": 30,
      "z": 42,
      "type": "hull_heavy"
    },
    {
      "x": 33,
      "y": 34,
      "z": 42,
      "type": "hull_heavy"
    },
    {
      "x": 34,
      "y": 30,
      "z": 42,
      "type": "hull_heavy"
    },
    {
      "x": 34,
      "y": 31,
      "z": 42,
      "type": "hull_heavy"
    },
    {
      "x": 34,
      "y": 32,
      "z": 42,
      "type": "hull_heavy"
    },
    {
      "x": 34,
      "y": 33,
      "z": 42,
      "type": "hull_heavy"
    },
    {
      "x": 34,
      "y": 34,
      "z": 42,
      "type": "hull_heavy"
    },
    {
      "x": 35,
      "y": 32,
      "z": 42,
      "type": "hull_heavy"
    },
    {
      "x": 54,
      "y": 32,
      "z": 32,
      "type": "hull_medium"
    },
    {
      "x": 55,
      "y": 31,
      "z": 31,
      "type": "hull_medium"
    },
    {
      "x": 55,
      "y": 31,
      "z": 32,
      "type": "hull_medium"
    },
    {
      "x": 55,
      "y": 31,
      "z": 33,
      "type": "hull_medium"
    },
    {
      "x": 55,
      "y": 32,
      "z": 31,
      "type": "hull_medium"
    },
    {
      "x": 55,
      "y": 32,
      "z": 32,
      "type": "hull_medium"
    },
    {
      "x": 55,
      "y": 32,
      "z": 33,
      "type": "hull_medium"
    },
    {
      "x": 55,
      "y": 33,
      "z": 31,
      "type": "hull_medium"
    },
    {
      "x": 55,
      "y": 33,
      "z": 32,
      "type": "hull_medium"
    },
    {
      "x": 55,
      "y": 33,
      "z": 33,
      "type": "hull_medium"
    },
    {
      "x": 56,
      "y": 30,
      "z": 32,
      "type": "hull_medium"
    },
    {
      "x": 56,
      "y": 31,
      "z": 31,
      "type": "hull_medium"
    },
    {
      "x": 56,
      "y": 31,
      "z": 32,
      "type": "hull_medium"
    },
    {
      "x": 56,
      "y": 31,
      "z": 33,
      "type": "hull_medium"
    },
    {
      "x": 56,
      "y": 32,
      "z": 30,
      "type": "hull_medium"
    },
    {
      "x": 56,
      "y": 32,
      "z": 31,
      "type": "hull_medium"
    },
    {
      "x": 56,
      "y": 32,
      "z": 32,
      "type": "hull_medium"
    },
    {
      "x": 56,
      "y": 32,
      "z": 33,
      "type": "hull_medium"
    },
    {
      "x": 56,
      "y": 32,
      "z": 34,
      "type": "hull_medium"
    },
    {
      "x": 56,
      "y": 33,
      "z": 31,
      "type": "hull_medium"
    },
    {
      "x": 56,
      "y": 33,
      "z": 32,
      "type": "hull_medium"
    },
    {
      "x": 56,
      "y": 33,
      "z": 33,
      "type": "hull_medium"
    },
    {
      "x": 56,
      "y": 34,
      "z": 32,
      "type": "hull_medium"
    },
    {
      "x": 57,
      "y": 31,
      "z": 31,
      "type": "hull_medium"
    },
    {
      "x": 57,
      "y": 31,
      "z": 32,
      "type": "hull_medium"
    },
    {
      "x": 57,
      "y": 31,
      "z": 33,
      "type": "hull_medium"
    },
    {
      "x": 57,
      "y": 32,
      "z": 31,
      "type": "hull_medium"
    },
    {
      "x": 57,
      "y": 32,
      "z": 32,
      "type": "hull_medium"
    },
    {
      "x": 57,
      "y": 32,
      "z": 33,
      "type": "hull_medium"
    },
    {
      "x": 57,
      "y": 33,
      "z": 31,
      "type": "hull_medium"
    },
    {
      "x": 57,
      "y": 33,
      "z": 32,
      "type": "hull_medium"
    },
    {
      "x": 57,
      "y": 33,
      "z": 33,
      "type": "hull_medium"
    },
    {
      "x": 58,
      "y": 32,
      "z": 32,
      "type": "hull_medium"
    },
    {
      "x": 53,
      "y": 36,
      "z": 32,
      "type": "hull_medium"
    },
    {
      "x": 54,
      "y": 35,
      "z": 31,
      "type": "hull_medium"
    },
    {
      "x": 54,
      "y": 35,
      "z": 32,
      "type": "hull_medium"
    },
    {
      "x": 54,
      "y": 35,
      "z": 33,
      "type": "hull_medium"
    },
    {
      "x": 54,
      "y": 36,
      "z": 31,
      "type": "hull_medium"
    },
    {
      "x": 54,
      "y": 36,
      "z": 32,
      "type": "hull_medium"
    },
    {
      "x": 54,
      "y": 36,
      "z": 33,
      "type": "hull_medium"
    },
    {
      "x": 54,
      "y": 37,
      "z": 31,
      "type": "hull_medium"
    },
    {
      "x": 54,
      "y": 37,
      "z": 32,
      "type": "hull_medium"
    },
    {
      "x": 54,
      "y": 37,
      "z": 33,
      "type": "hull_medium"
    },
    {
      "x": 55,
      "y": 34,
      "z": 32,
      "type": "hull_medium"
    },
    {
      "x": 55,
      "y": 35,
      "z": 31,
      "type": "hull_medium"
    },
    {
      "x": 55,
      "y": 35,
      "z": 32,
      "type": "hull_medium"
    },
    {
      "x": 55,
      "y": 35,
      "z": 33,
      "type": "hull_medium"
    },
    {
      "x": 55,
      "y": 36,
      "z": 30,
      "type": "hull_medium"
    },
    {
      "x": 55,
      "y": 36,
      "z": 31,
      "type": "hull_medium"
    },
    {
      "x": 55,
      "y": 36,
      "z": 32,
      "type": "hull_medium"
    },
    {
      "x": 55,
      "y": 36,
      "z": 33,
      "type": "hull_medium"
    },
    {
      "x": 55,
      "y": 36,
      "z": 34,
      "type": "hull_medium"
    },
    {
      "x": 55,
      "y": 37,
      "z": 31,
      "type": "hull_medium"
    },
    {
      "x": 55,
      "y": 37,
      "z": 32,
      "type": "hull_medium"
    },
    {
      "x": 55,
      "y": 37,
      "z": 33,
      "type": "hull_medium"
    },
    {
      "x": 55,
      "y": 38,
      "z": 32,
      "type": "hull_medium"
    },
    {
      "x": 56,
      "y": 35,
      "z": 31,
      "type": "hull_medium"
    },
    {
      "x": 56,
      "y": 35,
      "z": 32,
      "type": "hull_medium"
    },
    {
      "x": 56,
      "y": 35,
      "z": 33,
      "type": "hull_medium"
    },
    {
      "x": 56,
      "y": 36,
      "z": 31,
      "type": "hull_medium"
    },
    {
      "x": 56,
      "y": 36,
      "z": 32,
      "type": "hull_medium"
    },
    {
      "x": 56,
      "y": 36,
      "z": 33,
      "type": "hull_medium"
    },
    {
      "x": 56,
      "y": 37,
      "z": 31,
      "type": "hull_medium"
    },
    {
      "x": 56,
      "y": 37,
      "z": 32,
      "type": "hull_medium"
    },
    {
      "x": 56,
      "y": 37,
      "z": 33,
      "type": "hull_medium"
    },
    {
      "x": 57,
      "y": 36,
      "z": 32,
      "type": "hull_medium"
    },
    {
      "x": 52,
      "y": 41,
      "z": 32,
      "type": "hull_medium"
    },
    {
      "x": 53,
      "y": 40,
      "z": 31,
      "type": "hull_medium"
    },
    {
      "x": 53,
      "y": 40,
      "z": 32,
      "type": "hull_medium"
    },
    {
      "x": 53,
      "y": 40,
      "z": 33,
      "type": "hull_medium"
    },
    {
      "x": 53,
      "y": 41,
      "z": 31,
      "type": "hull_medium"
    },
    {
      "x": 53,
      "y": 41,
      "z": 32,
      "type": "hull_medium"
    },
    {
      "x": 53,
      "y": 41,
      "z": 33,
      "type": "hull_medium"
    },
    {
      "x": 53,
      "y": 42,
      "z": 31,
      "type": "hull_medium"
    },
    {
      "x": 53,
      "y": 42,
      "z": 32,
      "type": "hull_medium"
    },
    {
      "x": 53,
      "y": 42,
      "z": 33,
      "type": "hull_medium"
    },
    {
      "x": 54,
      "y": 39,
      "z": 32,
      "type": "hull_medium"
    },
    {
      "x": 54,
      "y": 40,
      "z": 31,
      "type": "hull_medium"
    },
    {
      "x": 54,
      "y": 40,
      "z": 32,
      "type": "hull_medium"
    },
    {
      "x": 54,
      "y": 40,
      "z": 33,
      "type": "hull_medium"
    },
    {
      "x": 54,
      "y": 41,
      "z": 30,
      "type": "hull_medium"
    },
    {
      "x": 54,
      "y": 41,
      "z": 31,
      "type": "hull_medium"
    },
    {
      "x": 54,
      "y": 41,
      "z": 32,
      "type": "hull_medium"
    },
    {
      "x": 54,
      "y": 41,
      "z": 33,
      "type": "hull_medium"
    },
    {
      "x": 54,
      "y": 41,
      "z": 34,
      "type": "hull_medium"
    },
    {
      "x": 54,
      "y": 42,
      "z": 31,
      "type": "hull_medium"
    },
    {
      "x": 54,
      "y": 42,
      "z": 32,
      "type": "hull_medium"
    },
    {
      "x": 54,
      "y": 42,
      "z": 33,
      "type": "hull_medium"
    },
    {
      "x": 54,
      "y": 43,
      "z": 32,
      "type": "hull_medium"
    },
    {
      "x": 55,
      "y": 40,
      "z": 31,
      "type": "hull_medium"
    },
    {
      "x": 55,
      "y": 40,
      "z": 32,
      "type": "hull_medium"
    },
    {
      "x": 55,
      "y": 40,
      "z": 33,
      "type": "hull_medium"
    },
    {
      "x": 55,
      "y": 41,
      "z": 31,
      "type": "hull_medium"
    },
    {
      "x": 55,
      "y": 41,
      "z": 32,
      "type": "hull_medium"
    },
    {
      "x": 55,
      "y": 41,
      "z": 33,
      "type": "hull_medium"
    },
    {
      "x": 55,
      "y": 42,
      "z": 31,
      "type": "hull_medium"
    },
    {
      "x": 55,
      "y": 42,
      "z": 32,
      "type": "hull_medium"
    },
    {
      "x": 55,
      "y": 42,
      "z": 33,
      "type": "hull_medium"
    },
    {
      "x": 56,
      "y": 41,
      "z": 32,
      "type": "hull_medium"
    },
    {
      "x": 49,
      "y": 45,
      "z": 32,
      "type": "hull_medium"
    },
    {
      "x": 50,
      "y": 44,
      "z": 31,
      "type": "hull_medium"
    },
    {
      "x": 50,
      "y": 44,
      "z": 32,
      "type": "hull_medium"
    },
    {
      "x": 50,
      "y": 44,
      "z": 33,
      "type": "hull_medium"
    },
    {
      "x": 50,
      "y": 45,
      "z": 31,
      "type": "hull_medium"
    },
    {
      "x": 50,
      "y": 45,
      "z": 32,
      "type": "hull_medium"
    },
    {
      "x": 50,
      "y": 45,
      "z": 33,
      "type": "hull_medium"
    },
    {
      "x": 50,
      "y": 46,
      "z": 31,
      "type": "hull_medium"
    },
    {
      "x": 50,
      "y": 46,
      "z": 32,
      "type": "hull_medium"
    },
    {
      "x": 50,
      "y": 46,
      "z": 33,
      "type": "hull_medium"
    },
    {
      "x": 51,
      "y": 43,
      "z": 32,
      "type": "hull_medium"
    },
    {
      "x": 51,
      "y": 44,
      "z": 31,
      "type": "hull_medium"
    },
    {
      "x": 51,
      "y": 44,
      "z": 32,
      "type": "hull_medium"
    },
    {
      "x": 51,
      "y": 44,
      "z": 33,
      "type": "hull_medium"
    },
    {
      "x": 51,
      "y": 45,
      "z": 30,
      "type": "hull_medium"
    },
    {
      "x": 51,
      "y": 45,
      "z": 31,
      "type": "hull_medium"
    },
    {
      "x": 51,
      "y": 45,
      "z": 32,
      "type": "hull_medium"
    },
    {
      "x": 51,
      "y": 45,
      "z": 33,
      "type": "hull_medium"
    },
    {
      "x": 51,
      "y": 45,
      "z": 34,
      "type": "hull_medium"
    },
    {
      "x": 51,
      "y": 46,
      "z": 31,
      "type": "hull_medium"
    },
    {
      "x": 51,
      "y": 46,
      "z": 32,
      "type": "hull_medium"
    },
    {
      "x": 51,
      "y": 46,
      "z": 33,
      "type": "hull_medium"
    },
    {
      "x": 51,
      "y": 47,
      "z": 32,
      "type": "hull_medium"
    },
    {
      "x": 52,
      "y": 44,
      "z": 31,
      "type": "hull_medium"
    },
    {
      "x": 52,
      "y": 44,
      "z": 32,
      "type": "hull_medium"
    },
    {
      "x": 52,
      "y": 44,
      "z": 33,
      "type": "hull_medium"
    },
    {
      "x": 52,
      "y": 45,
      "z": 31,
      "type": "hull_medium"
    },
    {
      "x": 52,
      "y": 45,
      "z": 32,
      "type": "hull_medium"
    },
    {
      "x": 52,
      "y": 45,
      "z": 33,
      "type": "hull_medium"
    },
    {
      "x": 52,
      "y": 46,
      "z": 31,
      "type": "hull_medium"
    },
    {
      "x": 52,
      "y": 46,
      "z": 32,
      "type": "hull_medium"
    },
    {
      "x": 52,
      "y": 46,
      "z": 33,
      "type": "hull_medium"
    },
    {
      "x": 53,
      "y": 45,
      "z": 32,
      "type": "hull_medium"
    },
    {
      "x": 46,
      "y": 48,
      "z": 32,
      "type": "hull_medium"
    },
    {
      "x": 47,
      "y": 47,
      "z": 31,
      "type": "hull_medium"
    },
    {
      "x": 47,
      "y": 47,
      "z": 32,
      "type": "hull_medium"
    },
    {
      "x": 47,
      "y": 47,
      "z": 33,
      "type": "hull_medium"
    },
    {
      "x": 47,
      "y": 48,
      "z": 31,
      "type": "hull_medium"
    },
    {
      "x": 47,
      "y": 48,
      "z": 32,
      "type": "hull_medium"
    },
    {
      "x": 47,
      "y": 48,
      "z": 33,
      "type": "hull_medium"
    },
    {
      "x": 47,
      "y": 49,
      "z": 31,
      "type": "hull_medium"
    },
    {
      "x": 47,
      "y": 49,
      "z": 32,
      "type": "hull_medium"
    },
    {
      "x": 47,
      "y": 49,
      "z": 33,
      "type": "hull_medium"
    },
    {
      "x": 48,
      "y": 46,
      "z": 32,
      "type": "hull_medium"
    },
    {
      "x": 48,
      "y": 47,
      "z": 31,
      "type": "hull_medium"
    },
    {
      "x": 48,
      "y": 47,
      "z": 32,
      "type": "hull_medium"
    },
    {
      "x": 48,
      "y": 47,
      "z": 33,
      "type": "hull_medium"
    },
    {
      "x": 48,
      "y": 48,
      "z": 30,
      "type": "hull_medium"
    },
    {
      "x": 48,
      "y": 48,
      "z": 31,
      "type": "hull_medium"
    },
    {
      "x": 48,
      "y": 48,
      "z": 32,
      "type": "hull_medium"
    },
    {
      "x": 48,
      "y": 48,
      "z": 33,
      "type": "hull_medium"
    },
    {
      "x": 48,
      "y": 48,
      "z": 34,
      "type": "hull_medium"
    },
    {
      "x": 48,
      "y": 49,
      "z": 31,
      "type": "hull_medium"
    },
    {
      "x": 48,
      "y": 49,
      "z": 32,
      "type": "hull_medium"
    },
    {
      "x": 48,
      "y": 49,
      "z": 33,
      "type": "hull_medium"
    },
    {
      "x": 48,
      "y": 50,
      "z": 32,
      "type": "hull_medium"
    },
    {
      "x": 49,
      "y": 47,
      "z": 31,
      "type": "hull_medium"
    },
    {
      "x": 49,
      "y": 47,
      "z": 32,
      "type": "hull_medium"
    },
    {
      "x": 49,
      "y": 47,
      "z": 33,
      "type": "hull_medium"
    },
    {
      "x": 49,
      "y": 48,
      "z": 31,
      "type": "hull_medium"
    },
    {
      "x": 49,
      "y": 48,
      "z": 32,
      "type": "hull_medium"
    },
    {
      "x": 49,
      "y": 48,
      "z": 33,
      "type": "hull_medium"
    },
    {
      "x": 49,
      "y": 49,
      "z": 31,
      "type": "hull_medium"
    },
    {
      "x": 49,
      "y": 49,
      "z": 32,
      "type": "hull_medium"
    },
    {
      "x": 49,
      "y": 49,
      "z": 33,
      "type": "hull_medium"
    },
    {
      "x": 50,
      "y": 48,
      "z": 32,
      "type": "hull_medium"
    },
    {
      "x": 43,
      "y": 51,
      "z": 32,
      "type": "hull_medium"
    },
    {
      "x": 44,
      "y": 50,
      "z": 31,
      "type": "hull_medium"
    },
    {
      "x": 44,
      "y": 50,
      "z": 32,
      "type": "hull_medium"
    },
    {
      "x": 44,
      "y": 50,
      "z": 33,
      "type": "hull_medium"
    },
    {
      "x": 44,
      "y": 51,
      "z": 31,
      "type": "hull_medium"
    },
    {
      "x": 44,
      "y": 51,
      "z": 32,
      "type": "hull_medium"
    },
    {
      "x": 44,
      "y": 51,
      "z": 33,
      "type": "hull_medium"
    },
    {
      "x": 44,
      "y": 52,
      "z": 31,
      "type": "hull_medium"
    },
    {
      "x": 44,
      "y": 52,
      "z": 32,
      "type": "hull_medium"
    },
    {
      "x": 44,
      "y": 52,
      "z": 33,
      "type": "hull_medium"
    },
    {
      "x": 45,
      "y": 49,
      "z": 32,
      "type": "hull_medium"
    },
    {
      "x": 45,
      "y": 50,
      "z": 31,
      "type": "hull_medium"
    },
    {
      "x": 45,
      "y": 50,
      "z": 32,
      "type": "hull_medium"
    },
    {
      "x": 45,
      "y": 50,
      "z": 33,
      "type": "hull_medium"
    },
    {
      "x": 45,
      "y": 51,
      "z": 30,
      "type": "hull_medium"
    },
    {
      "x": 45,
      "y": 51,
      "z": 31,
      "type": "hull_medium"
    },
    {
      "x": 45,
      "y": 51,
      "z": 32,
      "type": "hull_medium"
    },
    {
      "x": 45,
      "y": 51,
      "z": 33,
      "type": "hull_medium"
    },
    {
      "x": 45,
      "y": 51,
      "z": 34,
      "type": "hull_medium"
    },
    {
      "x": 45,
      "y": 52,
      "z": 31,
      "type": "hull_medium"
    },
    {
      "x": 45,
      "y": 52,
      "z": 32,
      "type": "hull_medium"
    },
    {
      "x": 45,
      "y": 52,
      "z": 33,
      "type": "hull_medium"
    },
    {
      "x": 45,
      "y": 53,
      "z": 32,
      "type": "hull_medium"
    },
    {
      "x": 46,
      "y": 50,
      "z": 31,
      "type": "hull_medium"
    },
    {
      "x": 46,
      "y": 50,
      "z": 32,
      "type": "hull_medium"
    },
    {
      "x": 46,
      "y": 50,
      "z": 33,
      "type": "hull_medium"
    },
    {
      "x": 46,
      "y": 51,
      "z": 31,
      "type": "hull_medium"
    },
    {
      "x": 46,
      "y": 51,
      "z": 32,
      "type": "hull_medium"
    },
    {
      "x": 46,
      "y": 51,
      "z": 33,
      "type": "hull_medium"
    },
    {
      "x": 46,
      "y": 52,
      "z": 31,
      "type": "hull_medium"
    },
    {
      "x": 46,
      "y": 52,
      "z": 32,
      "type": "hull_medium"
    },
    {
      "x": 46,
      "y": 52,
      "z": 33,
      "type": "hull_medium"
    },
    {
      "x": 47,
      "y": 51,
      "z": 32,
      "type": "hull_medium"
    },
    {
      "x": 39,
      "y": 54,
      "z": 32,
      "type": "hull_medium"
    },
    {
      "x": 40,
      "y": 53,
      "z": 31,
      "type": "hull_medium"
    },
    {
      "x": 40,
      "y": 53,
      "z": 32,
      "type": "hull_medium"
    },
    {
      "x": 40,
      "y": 53,
      "z": 33,
      "type": "hull_medium"
    },
    {
      "x": 40,
      "y": 54,
      "z": 31,
      "type": "hull_medium"
    },
    {
      "x": 40,
      "y": 54,
      "z": 32,
      "type": "hull_medium"
    },
    {
      "x": 40,
      "y": 54,
      "z": 33,
      "type": "hull_medium"
    },
    {
      "x": 40,
      "y": 55,
      "z": 31,
      "type": "hull_medium"
    },
    {
      "x": 40,
      "y": 55,
      "z": 32,
      "type": "hull_medium"
    },
    {
      "x": 40,
      "y": 55,
      "z": 33,
      "type": "hull_medium"
    },
    {
      "x": 41,
      "y": 52,
      "z": 32,
      "type": "hull_medium"
    },
    {
      "x": 41,
      "y": 53,
      "z": 31,
      "type": "hull_medium"
    },
    {
      "x": 41,
      "y": 53,
      "z": 32,
      "type": "hull_medium"
    },
    {
      "x": 41,
      "y": 53,
      "z": 33,
      "type": "hull_medium"
    },
    {
      "x": 41,
      "y": 54,
      "z": 30,
      "type": "hull_medium"
    },
    {
      "x": 41,
      "y": 54,
      "z": 31,
      "type": "hull_medium"
    },
    {
      "x": 41,
      "y": 54,
      "z": 32,
      "type": "hull_medium"
    },
    {
      "x": 41,
      "y": 54,
      "z": 33,
      "type": "hull_medium"
    },
    {
      "x": 41,
      "y": 54,
      "z": 34,
      "type": "hull_medium"
    },
    {
      "x": 41,
      "y": 55,
      "z": 31,
      "type": "hull_medium"
    },
    {
      "x": 41,
      "y": 55,
      "z": 32,
      "type": "hull_medium"
    },
    {
      "x": 41,
      "y": 55,
      "z": 33,
      "type": "hull_medium"
    },
    {
      "x": 41,
      "y": 56,
      "z": 32,
      "type": "hull_medium"
    },
    {
      "x": 42,
      "y": 53,
      "z": 31,
      "type": "hull_medium"
    },
    {
      "x": 42,
      "y": 53,
      "z": 32,
      "type": "hull_medium"
    },
    {
      "x": 42,
      "y": 53,
      "z": 33,
      "type": "hull_medium"
    },
    {
      "x": 42,
      "y": 54,
      "z": 31,
      "type": "hull_medium"
    },
    {
      "x": 42,
      "y": 54,
      "z": 32,
      "type": "hull_medium"
    },
    {
      "x": 42,
      "y": 54,
      "z": 33,
      "type": "hull_medium"
    },
    {
      "x": 42,
      "y": 55,
      "z": 31,
      "type": "hull_medium"
    },
    {
      "x": 42,
      "y": 55,
      "z": 32,
      "type": "hull_medium"
    },
    {
      "x": 42,
      "y": 55,
      "z": 33,
      "type": "hull_medium"
    },
    {
      "x": 43,
      "y": 54,
      "z": 32,
      "type": "hull_medium"
    },
    {
      "x": 34,
      "y": 55,
      "z": 32,
      "type": "hull_medium"
    },
    {
      "x": 35,
      "y": 54,
      "z": 31,
      "type": "hull_medium"
    },
    {
      "x": 35,
      "y": 54,
      "z": 32,
      "type": "hull_medium"
    },
    {
      "x": 35,
      "y": 54,
      "z": 33,
      "type": "hull_medium"
    },
    {
      "x": 35,
      "y": 55,
      "z": 31,
      "type": "hull_medium"
    },
    {
      "x": 35,
      "y": 55,
      "z": 32,
      "type": "hull_medium"
    },
    {
      "x": 35,
      "y": 55,
      "z": 33,
      "type": "hull_medium"
    },
    {
      "x": 35,
      "y": 56,
      "z": 31,
      "type": "hull_medium"
    },
    {
      "x": 35,
      "y": 56,
      "z": 32,
      "type": "hull_medium"
    },
    {
      "x": 35,
      "y": 56,
      "z": 33,
      "type": "hull_medium"
    },
    {
      "x": 36,
      "y": 53,
      "z": 32,
      "type": "hull_medium"
    },
    {
      "x": 36,
      "y": 54,
      "z": 31,
      "type": "hull_medium"
    },
    {
      "x": 36,
      "y": 54,
      "z": 32,
      "type": "hull_medium"
    },
    {
      "x": 36,
      "y": 54,
      "z": 33,
      "type": "hull_medium"
    },
    {
      "x": 36,
      "y": 55,
      "z": 30,
      "type": "hull_medium"
    },
    {
      "x": 36,
      "y": 55,
      "z": 31,
      "type": "hull_medium"
    },
    {
      "x": 36,
      "y": 55,
      "z": 32,
      "type": "hull_medium"
    },
    {
      "x": 36,
      "y": 55,
      "z": 33,
      "type": "hull_medium"
    },
    {
      "x": 36,
      "y": 55,
      "z": 34,
      "type": "hull_medium"
    },
    {
      "x": 36,
      "y": 56,
      "z": 31,
      "type": "hull_medium"
    },
    {
      "x": 36,
      "y": 56,
      "z": 32,
      "type": "hull_medium"
    },
    {
      "x": 36,
      "y": 56,
      "z": 33,
      "type": "hull_medium"
    },
    {
      "x": 36,
      "y": 57,
      "z": 32,
      "type": "hull_medium"
    },
    {
      "x": 37,
      "y": 54,
      "z": 31,
      "type": "hull_medium"
    },
    {
      "x": 37,
      "y": 54,
      "z": 32,
      "type": "hull_medium"
    },
    {
      "x": 37,
      "y": 54,
      "z": 33,
      "type": "hull_medium"
    },
    {
      "x": 37,
      "y": 55,
      "z": 31,
      "type": "hull_medium"
    },
    {
      "x": 37,
      "y": 55,
      "z": 32,
      "type": "hull_medium"
    },
    {
      "x": 37,
      "y": 55,
      "z": 33,
      "type": "hull_medium"
    },
    {
      "x": 37,
      "y": 56,
      "z": 31,
      "type": "hull_medium"
    },
    {
      "x": 37,
      "y": 56,
      "z": 32,
      "type": "hull_medium"
    },
    {
      "x": 37,
      "y": 56,
      "z": 33,
      "type": "hull_medium"
    },
    {
      "x": 38,
      "y": 55,
      "z": 32,
      "type": "hull_medium"
    },
    {
      "x": 30,
      "y": 56,
      "z": 32,
      "type": "hull_medium"
    },
    {
      "x": 31,
      "y": 55,
      "z": 31,
      "type": "hull_medium"
    },
    {
      "x": 31,
      "y": 55,
      "z": 32,
      "type": "hull_medium"
    },
    {
      "x": 31,
      "y": 55,
      "z": 33,
      "type": "hull_medium"
    },
    {
      "x": 31,
      "y": 56,
      "z": 31,
      "type": "hull_medium"
    },
    {
      "x": 31,
      "y": 56,
      "z": 32,
      "type": "hull_medium"
    },
    {
      "x": 31,
      "y": 56,
      "z": 33,
      "type": "hull_medium"
    },
    {
      "x": 31,
      "y": 57,
      "z": 31,
      "type": "hull_medium"
    },
    {
      "x": 31,
      "y": 57,
      "z": 32,
      "type": "hull_medium"
    },
    {
      "x": 31,
      "y": 57,
      "z": 33,
      "type": "hull_medium"
    },
    {
      "x": 32,
      "y": 54,
      "z": 32,
      "type": "hull_medium"
    },
    {
      "x": 32,
      "y": 55,
      "z": 31,
      "type": "hull_medium"
    },
    {
      "x": 32,
      "y": 55,
      "z": 32,
      "type": "hull_medium"
    },
    {
      "x": 32,
      "y": 55,
      "z": 33,
      "type": "hull_medium"
    },
    {
      "x": 32,
      "y": 56,
      "z": 30,
      "type": "hull_medium"
    },
    {
      "x": 32,
      "y": 56,
      "z": 31,
      "type": "hull_medium"
    },
    {
      "x": 32,
      "y": 56,
      "z": 32,
      "type": "hull_medium"
    },
    {
      "x": 32,
      "y": 56,
      "z": 33,
      "type": "hull_medium"
    },
    {
      "x": 32,
      "y": 56,
      "z": 34,
      "type": "hull_medium"
    },
    {
      "x": 32,
      "y": 57,
      "z": 31,
      "type": "hull_medium"
    },
    {
      "x": 32,
      "y": 57,
      "z": 32,
      "type": "hull_medium"
    },
    {
      "x": 32,
      "y": 57,
      "z": 33,
      "type": "hull_medium"
    },
    {
      "x": 32,
      "y": 58,
      "z": 32,
      "type": "hull_medium"
    },
    {
      "x": 33,
      "y": 55,
      "z": 31,
      "type": "hull_medium"
    },
    {
      "x": 33,
      "y": 55,
      "z": 32,
      "type": "hull_medium"
    },
    {
      "x": 33,
      "y": 55,
      "z": 33,
      "type": "hull_medium"
    },
    {
      "x": 33,
      "y": 56,
      "z": 31,
      "type": "hull_medium"
    },
    {
      "x": 33,
      "y": 56,
      "z": 32,
      "type": "hull_medium"
    },
    {
      "x": 33,
      "y": 56,
      "z": 33,
      "type": "hull_medium"
    },
    {
      "x": 33,
      "y": 57,
      "z": 31,
      "type": "hull_medium"
    },
    {
      "x": 33,
      "y": 57,
      "z": 32,
      "type": "hull_medium"
    },
    {
      "x": 33,
      "y": 57,
      "z": 33,
      "type": "hull_medium"
    },
    {
      "x": 34,
      "y": 56,
      "z": 32,
      "type": "hull_medium"
    },
    {
      "x": 26,
      "y": 55,
      "z": 32,
      "type": "hull_medium"
    },
    {
      "x": 27,
      "y": 54,
      "z": 31,
      "type": "hull_medium"
    },
    {
      "x": 27,
      "y": 54,
      "z": 32,
      "type": "hull_medium"
    },
    {
      "x": 27,
      "y": 54,
      "z": 33,
      "type": "hull_medium"
    },
    {
      "x": 27,
      "y": 55,
      "z": 31,
      "type": "hull_medium"
    },
    {
      "x": 27,
      "y": 55,
      "z": 32,
      "type": "hull_medium"
    },
    {
      "x": 27,
      "y": 55,
      "z": 33,
      "type": "hull_medium"
    },
    {
      "x": 27,
      "y": 56,
      "z": 31,
      "type": "hull_medium"
    },
    {
      "x": 27,
      "y": 56,
      "z": 32,
      "type": "hull_medium"
    },
    {
      "x": 27,
      "y": 56,
      "z": 33,
      "type": "hull_medium"
    },
    {
      "x": 28,
      "y": 53,
      "z": 32,
      "type": "hull_medium"
    },
    {
      "x": 28,
      "y": 54,
      "z": 31,
      "type": "hull_medium"
    },
    {
      "x": 28,
      "y": 54,
      "z": 32,
      "type": "hull_medium"
    },
    {
      "x": 28,
      "y": 54,
      "z": 33,
      "type": "hull_medium"
    },
    {
      "x": 28,
      "y": 55,
      "z": 30,
      "type": "hull_medium"
    },
    {
      "x": 28,
      "y": 55,
      "z": 31,
      "type": "hull_medium"
    },
    {
      "x": 28,
      "y": 55,
      "z": 32,
      "type": "hull_medium"
    },
    {
      "x": 28,
      "y": 55,
      "z": 33,
      "type": "hull_medium"
    },
    {
      "x": 28,
      "y": 55,
      "z": 34,
      "type": "hull_medium"
    },
    {
      "x": 28,
      "y": 56,
      "z": 31,
      "type": "hull_medium"
    },
    {
      "x": 28,
      "y": 56,
      "z": 32,
      "type": "hull_medium"
    },
    {
      "x": 28,
      "y": 56,
      "z": 33,
      "type": "hull_medium"
    },
    {
      "x": 28,
      "y": 57,
      "z": 32,
      "type": "hull_medium"
    },
    {
      "x": 29,
      "y": 54,
      "z": 31,
      "type": "hull_medium"
    },
    {
      "x": 29,
      "y": 54,
      "z": 32,
      "type": "hull_medium"
    },
    {
      "x": 29,
      "y": 54,
      "z": 33,
      "type": "hull_medium"
    },
    {
      "x": 29,
      "y": 55,
      "z": 31,
      "type": "hull_medium"
    },
    {
      "x": 29,
      "y": 55,
      "z": 32,
      "type": "hull_medium"
    },
    {
      "x": 29,
      "y": 55,
      "z": 33,
      "type": "hull_medium"
    },
    {
      "x": 29,
      "y": 56,
      "z": 31,
      "type": "hull_medium"
    },
    {
      "x": 29,
      "y": 56,
      "z": 32,
      "type": "hull_medium"
    },
    {
      "x": 29,
      "y": 56,
      "z": 33,
      "type": "hull_medium"
    },
    {
      "x": 30,
      "y": 55,
      "z": 32,
      "type": "hull_medium"
    },
    {
      "x": 21,
      "y": 54,
      "z": 32,
      "type": "hull_medium"
    },
    {
      "x": 22,
      "y": 53,
      "z": 31,
      "type": "hull_medium"
    },
    {
      "x": 22,
      "y": 53,
      "z": 32,
      "type": "hull_medium"
    },
    {
      "x": 22,
      "y": 53,
      "z": 33,
      "type": "hull_medium"
    },
    {
      "x": 22,
      "y": 54,
      "z": 31,
      "type": "hull_medium"
    },
    {
      "x": 22,
      "y": 54,
      "z": 32,
      "type": "hull_medium"
    },
    {
      "x": 22,
      "y": 54,
      "z": 33,
      "type": "hull_medium"
    },
    {
      "x": 22,
      "y": 55,
      "z": 31,
      "type": "hull_medium"
    },
    {
      "x": 22,
      "y": 55,
      "z": 32,
      "type": "hull_medium"
    },
    {
      "x": 22,
      "y": 55,
      "z": 33,
      "type": "hull_medium"
    },
    {
      "x": 23,
      "y": 52,
      "z": 32,
      "type": "hull_medium"
    },
    {
      "x": 23,
      "y": 53,
      "z": 31,
      "type": "hull_medium"
    },
    {
      "x": 23,
      "y": 53,
      "z": 32,
      "type": "hull_medium"
    },
    {
      "x": 23,
      "y": 53,
      "z": 33,
      "type": "hull_medium"
    },
    {
      "x": 23,
      "y": 54,
      "z": 30,
      "type": "hull_medium"
    },
    {
      "x": 23,
      "y": 54,
      "z": 31,
      "type": "hull_medium"
    },
    {
      "x": 23,
      "y": 54,
      "z": 32,
      "type": "hull_medium"
    },
    {
      "x": 23,
      "y": 54,
      "z": 33,
      "type": "hull_medium"
    },
    {
      "x": 23,
      "y": 54,
      "z": 34,
      "type": "hull_medium"
    },
    {
      "x": 23,
      "y": 55,
      "z": 31,
      "type": "hull_medium"
    },
    {
      "x": 23,
      "y": 55,
      "z": 32,
      "type": "hull_medium"
    },
    {
      "x": 23,
      "y": 55,
      "z": 33,
      "type": "hull_medium"
    },
    {
      "x": 23,
      "y": 56,
      "z": 32,
      "type": "hull_medium"
    },
    {
      "x": 24,
      "y": 53,
      "z": 31,
      "type": "hull_medium"
    },
    {
      "x": 24,
      "y": 53,
      "z": 32,
      "type": "hull_medium"
    },
    {
      "x": 24,
      "y": 53,
      "z": 33,
      "type": "hull_medium"
    },
    {
      "x": 24,
      "y": 54,
      "z": 31,
      "type": "hull_medium"
    },
    {
      "x": 24,
      "y": 54,
      "z": 32,
      "type": "hull_medium"
    },
    {
      "x": 24,
      "y": 54,
      "z": 33,
      "type": "hull_medium"
    },
    {
      "x": 24,
      "y": 55,
      "z": 31,
      "type": "hull_medium"
    },
    {
      "x": 24,
      "y": 55,
      "z": 32,
      "type": "hull_medium"
    },
    {
      "x": 24,
      "y": 55,
      "z": 33,
      "type": "hull_medium"
    },
    {
      "x": 25,
      "y": 54,
      "z": 32,
      "type": "hull_medium"
    },
    {
      "x": 17,
      "y": 51,
      "z": 32,
      "type": "hull_medium"
    },
    {
      "x": 18,
      "y": 50,
      "z": 31,
      "type": "hull_medium"
    },
    {
      "x": 18,
      "y": 50,
      "z": 32,
      "type": "hull_medium"
    },
    {
      "x": 18,
      "y": 50,
      "z": 33,
      "type": "hull_medium"
    },
    {
      "x": 18,
      "y": 51,
      "z": 31,
      "type": "hull_medium"
    },
    {
      "x": 18,
      "y": 51,
      "z": 32,
      "type": "hull_medium"
    },
    {
      "x": 18,
      "y": 51,
      "z": 33,
      "type": "hull_medium"
    },
    {
      "x": 18,
      "y": 52,
      "z": 31,
      "type": "hull_medium"
    },
    {
      "x": 18,
      "y": 52,
      "z": 32,
      "type": "hull_medium"
    },
    {
      "x": 18,
      "y": 52,
      "z": 33,
      "type": "hull_medium"
    },
    {
      "x": 19,
      "y": 49,
      "z": 32,
      "type": "hull_medium"
    },
    {
      "x": 19,
      "y": 50,
      "z": 31,
      "type": "hull_medium"
    },
    {
      "x": 19,
      "y": 50,
      "z": 32,
      "type": "hull_medium"
    },
    {
      "x": 19,
      "y": 50,
      "z": 33,
      "type": "hull_medium"
    },
    {
      "x": 19,
      "y": 51,
      "z": 30,
      "type": "hull_medium"
    },
    {
      "x": 19,
      "y": 51,
      "z": 31,
      "type": "hull_medium"
    },
    {
      "x": 19,
      "y": 51,
      "z": 32,
      "type": "hull_medium"
    },
    {
      "x": 19,
      "y": 51,
      "z": 33,
      "type": "hull_medium"
    },
    {
      "x": 19,
      "y": 51,
      "z": 34,
      "type": "hull_medium"
    },
    {
      "x": 19,
      "y": 52,
      "z": 31,
      "type": "hull_medium"
    },
    {
      "x": 19,
      "y": 52,
      "z": 32,
      "type": "hull_medium"
    },
    {
      "x": 19,
      "y": 52,
      "z": 33,
      "type": "hull_medium"
    },
    {
      "x": 19,
      "y": 53,
      "z": 32,
      "type": "hull_medium"
    },
    {
      "x": 20,
      "y": 50,
      "z": 31,
      "type": "hull_medium"
    },
    {
      "x": 20,
      "y": 50,
      "z": 32,
      "type": "hull_medium"
    },
    {
      "x": 20,
      "y": 50,
      "z": 33,
      "type": "hull_medium"
    },
    {
      "x": 20,
      "y": 51,
      "z": 31,
      "type": "hull_medium"
    },
    {
      "x": 20,
      "y": 51,
      "z": 32,
      "type": "hull_medium"
    },
    {
      "x": 20,
      "y": 51,
      "z": 33,
      "type": "hull_medium"
    },
    {
      "x": 20,
      "y": 52,
      "z": 31,
      "type": "hull_medium"
    },
    {
      "x": 20,
      "y": 52,
      "z": 32,
      "type": "hull_medium"
    },
    {
      "x": 20,
      "y": 52,
      "z": 33,
      "type": "hull_medium"
    },
    {
      "x": 21,
      "y": 51,
      "z": 32,
      "type": "hull_medium"
    },
    {
      "x": 14,
      "y": 48,
      "z": 32,
      "type": "hull_medium"
    },
    {
      "x": 15,
      "y": 47,
      "z": 31,
      "type": "hull_medium"
    },
    {
      "x": 15,
      "y": 47,
      "z": 32,
      "type": "hull_medium"
    },
    {
      "x": 15,
      "y": 47,
      "z": 33,
      "type": "hull_medium"
    },
    {
      "x": 15,
      "y": 48,
      "z": 31,
      "type": "hull_medium"
    },
    {
      "x": 15,
      "y": 48,
      "z": 32,
      "type": "hull_medium"
    },
    {
      "x": 15,
      "y": 48,
      "z": 33,
      "type": "hull_medium"
    },
    {
      "x": 15,
      "y": 49,
      "z": 31,
      "type": "hull_medium"
    },
    {
      "x": 15,
      "y": 49,
      "z": 32,
      "type": "hull_medium"
    },
    {
      "x": 15,
      "y": 49,
      "z": 33,
      "type": "hull_medium"
    },
    {
      "x": 16,
      "y": 46,
      "z": 32,
      "type": "hull_medium"
    },
    {
      "x": 16,
      "y": 47,
      "z": 31,
      "type": "hull_medium"
    },
    {
      "x": 16,
      "y": 47,
      "z": 32,
      "type": "hull_medium"
    },
    {
      "x": 16,
      "y": 47,
      "z": 33,
      "type": "hull_medium"
    },
    {
      "x": 16,
      "y": 48,
      "z": 30,
      "type": "hull_medium"
    },
    {
      "x": 16,
      "y": 48,
      "z": 31,
