{
  "name": "Export",
  "version": "1.0",
  "createdAt": "2026-03-14T14:13:54.136Z",
  "gridSize": 64,
  "voxelCount": 143,
  "voxels": [
    {
      "x": 25,
      "y": 32,
      "z": 35,
      "type": "battery"
    },
    {
      "x": 27,
      "y": 32,
      "z": 29,
      "type": "light"
    },
    {
      "x": 28,
      "y": 32,
      "z": 29,
      "type": "battery"
    },
    {
      "x": 32,
      "y": 32,
      "z": 28,
      "type": "light"
    },
    {
      "x": 32,
      "y": 32,
      "z": 31,
      "type": "shield_gen"
    },
    {
      "x": 32,
      "y": 32,
      "z": 32,
      "type": "hull_medium"
    },
    {
      "x": 32,
      "y": 32,
      "z": 33,
      "type": "shield_gen"
    },
    {
      "x": 32,
      "y": 32,
      "z": 34,
      "type": "shield_gen"
    },
    {
      "x": 32,
      "y": 32,
      "z": 35,
      "type": "shield_gen"
    },
    {
      "x": 32,
      "y": 32,
      "z": 36,
      "type": "shield_gen"
    },
    {
      "x": 32,
      "y": 33,
      "z": 31,
      "type": "battery"
    },
    {
      "x": 32,
      "y": 33,
      "z": 32,
      "type": "battery"
    },
    {
      "x": 32,
      "y": 33,
      "z": 33,
      "type": "thruster"
    },
    {
      "x": 32,
      "y": 33,
      "z": 34,
      "type": "cargo_bay"
    },
    {
      "x": 32,
      "y": 33,
      "z": 35,
      "type": "cargo_bay"
    },
    {
      "x": 32,
      "y": 33,
      "z": 36,
      "type": "thruster"
    },
    {
      "x": 33,
      "y": 32,
      "z": 31,
      "type": "shield_gen"
    },
    {
      "x": 33,
      "y": 32,
      "z": 32,
      "type": "hull_medium"
    },
    {
      "x": 33,
      "y": 32,
      "z": 33,
      "type": "shield_gen"
    },
    {
      "x": 33,
      "y": 32,
      "z": 34,
      "type": "shield_gen"
    },
    {
      "x": 33,
      "y": 32,
      "z": 35,
      "type": "shield_gen"
    },
    {
      "x": 33,
      "y": 32,
      "z": 36,
      "type": "shield_gen"
    },
    {
      "x": 33,
      "y": 33,
      "z": 31,
      "type": "battery"
    },
    {
      "x": 33,
      "y": 33,
      "z": 32,
      "type": "battery"
    },
    {
      "x": 33,
      "y": 33,
      "z": 33,
      "type": "thruster"
    },
    {
      "x": 33,
      "y": 33,
      "z": 34,
      "type": "cargo_bay"
    },
    {
      "x": 33,
      "y": 33,
      "z": 35,
      "type": "cargo_bay"
    },
    {
      "x": 33,
      "y": 33,
      "z": 36,
      "type": "thruster"
    },
    {
      "x": 33,
      "y": 34,
      "z": 31,
      "type": "turret_mount"
    },
    {
      "x": 33,
      "y": 34,
      "z": 32,
      "type": "turret_mount"
    },
    {
      "x": 33,
      "y": 34,
      "z": 33,
      "type": "turret_mount"
    },
    {
      "x": 33,
      "y": 34,
      "z": 34,
      "type": "turret_mount"
    },
    {
      "x": 33,
      "y": 34,
      "z": 35,
      "type": "turret_mount"
    },
    {
      "x": 33,
      "y": 35,
      "z": 31,
      "type": "light"
    },
    {
      "x": 33,
      "y": 35,
      "z": 32,
      "type": "light"
    },
    {
      "x": 33,
      "y": 35,
      "z": 33,
      "type": "turret_mount"
    },
    {
      "x": 33,
      "y": 35,
      "z": 34,
      "type": "light"
    },
    {
      "x": 33,
      "y": 35,
      "z": 35,
      "type": "light"
    },
    {
      "x": 33,
      "y": 36,
      "z": 33,
      "type": "thruster"
    },
    {
      "x": 34,
      "y": 32,
      "z": 26,
      "type": "light"
    },
    {
      "x": 34,
      "y": 32,
      "z": 31,
      "type": "shield_gen"
    },
    {
      "x": 34,
      "y": 32,
      "z": 32,
      "type": "hull_medium"
    },
    {
      "x": 34,
      "y": 32,
      "z": 33,
      "type": "hull_medium"
    },
    {
      "x": 34,
      "y": 32,
      "z": 34,
      "type": "hull_medium"
    },
    {
      "x": 34,
      "y": 32,
      "z": 35,
      "type": "hull_medium"
    },
    {
      "x": 34,
      "y": 32,
      "z": 36,
      "type": "hull_medium"
    },
    {
      "x": 34,
      "y": 33,
      "z": 31,
      "type": "battery"
    },
    {
      "x": 34,
      "y": 33,
      "z": 32,
      "type": "battery"
    },
    {
      "x": 34,
      "y": 33,
      "z": 33,
      "type": "battery"
    },
    {
      "x": 34,
      "y": 33,
      "z": 34,
      "type": "battery"
    },
    {
      "x": 34,
      "y": 33,
      "z": 35,
      "type": "battery"
    },
    {
      "x": 34,
      "y": 33,
      "z": 36,
      "type": "battery"
    },
    {
      "x": 34,
      "y": 34,
      "z": 31,
      "type": "turret_mount"
    },
    {
      "x": 34,
      "y": 34,
      "z": 32,
      "type": "turret_mount"
    },
    {
      "x": 34,
      "y": 34,
      "z": 33,
      "type": "turret_mount"
    },
    {
      "x": 34,
      "y": 34,
      "z": 34,
      "type": "turret_mount"
    },
    {
      "x": 34,
      "y": 34,
      "z": 35,
      "type": "turret_mount"
    },
    {
      "x": 34,
      "y": 35,
      "z": 31,
      "type": "light"
    },
    {
      "x": 34,
      "y": 35,
      "z": 32,
      "type": "light"
    },
    {
      "x": 34,
      "y": 35,
      "z": 33,
      "type": "turret_mount"
    },
    {
      "x": 34,
      "y": 35,
      "z": 34,
      "type": "light"
    },
    {
      "x": 34,
      "y": 35,
      "z": 35,
      "type": "light"
    },
    {
      "x": 34,
      "y": 36,
      "z": 33,
      "type": "shield_gen"
    },
    {
      "x": 35,
      "y": 32,
      "z": 28,
      "type": "battery"
    },
    {
      "x": 35,
      "y": 32,
      "z": 31,
      "type": "shield_gen"
    },
    {
      "x": 35,
      "y": 32,
      "z": 32,
      "type": "hull_medium"
    },
    {
      "x": 35,
      "y": 32,
      "z": 33,
      "type": "shield_gen"
    },
    {
      "x": 35,
      "y": 32,
      "z": 34,
      "type": "shield_gen"
    },
    {
      "x": 35,
      "y": 32,
      "z": 35,
      "type": "shield_gen"
    },
    {
      "x": 35,
      "y": 32,
      "z": 36,
      "type": "shield_gen"
    },
    {
      "x": 35,
      "y": 33,
      "z": 31,
      "type": "battery"
    },
    {
      "x": 35,
      "y": 33,
      "z": 32,
      "type": "battery"
    },
    {
      "x": 35,
      "y": 33,
      "z": 33,
      "type": "battery"
    },
    {
      "x": 35,
      "y": 33,
      "z": 34,
      "type": "battery"
    },
    {
      "x": 35,
      "y": 33,
      "z": 35,
      "type": "battery"
    },
    {
      "x": 35,
      "y": 33,
      "z": 36,
      "type": "battery"
    },
    {
      "x": 35,
      "y": 34,
      "z": 31,
      "type": "turret_mount"
    },
    {
      "x": 35,
      "y": 34,
      "z": 32,
      "type": "battery"
    },
    {
      "x": 35,
      "y": 34,
      "z": 33,
      "type": "battery"
    },
    {
      "x": 35,
      "y": 34,
      "z": 34,
      "type": "battery"
    },
    {
      "x": 35,
      "y": 34,
      "z": 35,
      "type": "turret_mount"
    },
    {
      "x": 35,
      "y": 35,
      "z": 31,
      "type": "turret_mount"
    },
    {
      "x": 35,
      "y": 35,
      "z": 32,
      "type": "cargo_bay"
    },
    {
      "x": 35,
      "y": 35,
      "z": 33,
      "type": "turret_mount"
    },
    {
      "x": 35,
      "y": 35,
      "z": 34,
      "type": "cargo_bay"
    },
    {
      "x": 35,
      "y": 35,
      "z": 35,
      "type": "turret_mount"
    },
    {
      "x": 35,
      "y": 36,
      "z": 31,
      "type": "thruster"
    },
    {
      "x": 35,
      "y": 36,
      "z": 32,
      "type": "shield_gen"
    },
    {
      "x": 35,
      "y": 36,
      "z": 33,
      "type": "thruster"
    },
    {
      "x": 35,
      "y": 36,
      "z": 34,
      "type": "shield_gen"
    },
    {
      "x": 35,
      "y": 36,
      "z": 35,
      "type": "thruster"
    },
    {
      "x": 35,
      "y": 37,
      "z": 33,
      "type": "shield_gen"
    },
    {
      "x": 36,
      "y": 32,
      "z": 31,
      "type": "hull_medium"
    },
    {
      "x": 36,
      "y": 32,
      "z": 32,
      "type": "hull_medium"
    },
    {
      "x": 36,
      "y": 32,
      "z": 33,
      "type": "shield_gen"
    },
    {
      "x": 36,
      "y": 32,
      "z": 34,
      "type": "shield_gen"
    },
    {
      "x": 36,
      "y": 32,
      "z": 35,
      "type": "shield_gen"
    },
    {
      "x": 36,
      "y": 32,
      "z": 36,
      "type": "shield_gen"
    },
    {
      "x": 36,
      "y": 33,
      "z": 31,
      "type": "shield_gen"
    },
    {
      "x": 36,
      "y": 33,
      "z": 32,
      "type": "battery"
    },
    {
      "x": 36,
      "y": 33,
      "z": 33,
      "type": "battery"
    },
    {
      "x": 36,
      "y": 33,
      "z": 34,
      "type": "battery"
    },
    {
      "x": 36,
      "y": 33,
      "z": 35,
      "type": "battery"
    },
    {
      "x": 36,
      "y": 33,
      "z": 36,
      "type": "battery"
    },
    {
      "x": 36,
      "y": 34,
      "z": 31,
      "type": "battery"
    },
    {
      "x": 36,
      "y": 34,
      "z": 32,
      "type": "thruster"
    },
    {
      "x": 36,
      "y": 34,
      "z": 33,
      "type": "thruster"
    },
    {
      "x": 36,
      "y": 34,
      "z": 34,
      "type": "thruster"
    },
    {
      "x": 36,
      "y": 34,
      "z": 35,
      "type": "battery"
    },
    {
      "x": 36,
      "y": 35,
      "z": 31,
      "type": "light"
    },
    {
      "x": 36,
      "y": 35,
      "z": 32,
      "type": "light"
    },
    {
      "x": 36,
      "y": 35,
      "z": 33,
      "type": "cargo_bay"
    },
    {
      "x": 36,
      "y": 35,
      "z": 34,
      "type": "light"
    },
    {
      "x": 36,
      "y": 35,
      "z": 35,
      "type": "light"
    },
    {
      "x": 36,
      "y": 36,
      "z": 33,
      "type": "shield_gen"
    },
    {
      "x": 36,
      "y": 36,
      "z": 35,
      "type": "light"
    },
    {
      "x": 37,
      "y": 32,
      "z": 31,
      "type": "shield_gen"
    },
    {
      "x": 37,
      "y": 32,
      "z": 32,
      "type": "hull_medium"
    },
    {
      "x": 37,
      "y": 32,
      "z": 33,
      "type": "shield_gen"
    },
    {
      "x": 37,
      "y": 32,
      "z": 34,
      "type": "shield_gen"
    },
    {
      "x": 37,
      "y": 32,
      "z": 35,
      "type": "shield_gen"
    },
    {
      "x": 37,
      "y": 32,
      "z": 36,
      "type": "shield_gen"
    },
    {
      "x": 37,
      "y": 33,
      "z": 31,
      "type": "battery"
    },
    {
      "x": 37,
      "y": 33,
      "z": 32,
      "type": "battery"
    },
    {
      "x": 37,
      "y": 33,
      "z": 33,
      "type": "battery"
    },
    {
      "x": 37,
      "y": 33,
      "z": 34,
      "type": "battery"
    },
    {
      "x": 37,
      "y": 33,
      "z": 35,
      "type": "battery"
    },
    {
      "x": 37,
      "y": 33,
      "z": 36,
      "type": "battery"
    },
    {
      "x": 37,
      "y": 34,
      "z": 31,
      "type": "light"
    },
    {
      "x": 37,
      "y": 34,
      "z": 32,
      "type": "battery"
    },
    {
      "x": 37,
      "y": 34,
      "z": 33,
      "type": "battery"
    },
    {
      "x": 37,
      "y": 34,
      "z": 34,
      "type": "battery"
    },
    {
      "x": 37,
      "y": 34,
      "z": 35,
      "type": "light"
    },
    {
      "x": 37,
      "y": 35,
      "z": 31,
      "type": "light"
    },
    {
      "x": 37,
      "y": 35,
      "z": 32,
      "type": "light"
    },
    {
      "x": 37,
      "y": 35,
      "z": 33,
      "type": "turret_mount"
    },
    {
      "x": 37,
      "y": 35,
      "z": 34,
      "type": "light"
    },
    {
      "x": 37,
      "y": 35,
      "z": 35,
      "type": "light"
    },
    {
      "x": 37,
      "y": 36,
      "z": 33,
      "type": "thruster"
    },
    {
      "x": 38,
      "y": 32,
      "z": 38,
      "type": "light"
    },
    {
      "x": 40,
      "y": 32,
      "z": 33,
      "type": "battery"
    },
    {
      "x": 41,
      "y": 32,
      "z": 34,
      "type": "light"
    },
    {
      "x": 44,
      "y": 32,
      "z": 44,
      "type": "turret_mount"
    }
  ]
}